Workbook
Name BoxPlot: "BoxPlot"
Name Bubble: "Bubble"
Name Candlestick: "Candlestick"
Name Chart: "Chart"
Name ChartImage: "ChartImage"
Name ColumnRange: "ColumnRange"
Name Dumbbell: "Dumbbell"
Name Heatmap: "Heatmap"
Name Histogram: "Histogram"
Name Map: "Map"
Name OHLC: "OHLC"
Name PieChart: "PieChart"
Name Scatter: "Scatter"
Name Series: "Series"
Name Stripe: "Stripe"
Name Table: "Table"
Name TreeMap: "TreeMap"
Name Waterfall: "Waterfall"

Sheet Instructions
B3: Instructions to update the file
B6: Link to Vahan portal - Tabular Summary:
B7: https://vahan.parivahan.gov.in/vahan4dashboard/vahan/view/reportview.xhtml
B9: Extract Maker-wise monthly data for required categories. Use panel on the left to filter for below-mentioned classification.
B11: Vahan classification used:
B12: Type | C12: Broad categorization | D12: Vehicle Classification used
B13: PVs | C13: Vehicle Class | D13: MOTOR CAB + MOTOR CAR
B14: 2Ws | C14: Vehicle Category | D14: TWO WHEELER (Invalid Carriage), TWO WHEELER(NT), TWO WHEELER(T)
B15: 3Ws | C15: Vehicle Class | D15: THREE WHEELER (GOODS) + THREE WHEELER (PASSENGER)
B16: Tractors | C16: Vehicle Class | D16: AGRICULTURAL TRACTOR + TRACTOR (COMMERCIAL)
B17: EV PVs | C17: Fuels | D17: ELECTRIC(BOV) + PURE EV + PVs as above
B18: EV 2Ws | C18: Fuels | D18: ELECTRIC(BOV) + PURE EV + 2Ws as above
B19: EV 3Ws | C19: Fuels | D19: ELECTRIC(BOV) + PURE EV + 3Ws as above
B20: PV CNG | C20: Fuels | D20: CNG ONLY + PETROL/CNG + PETROL(E20)/CNG + PVs as above
B21: PV Strong Hybrid | C21: Fuels | D21: PLUG-IN HYBRID EV + STRONG HYBRID EV + PVs as above
B22: LCVs | C22: Vehicle Category | D22: LIGHT GOODS VEHICLE
B23: MHCVs | C23: Vehicle Category | D23: HEAVY GOODS VEHICLE + HEAVY PASSENGER VEHICLE + MEDIUM GOODS VEHICLE + MEDIUM PASSENGER VEHICLE
B24: CVs | C24: Vehicle Category | D24: LCVs + MHCVs as above
B26: Download the data in excel after running each of the above criterion. Numbers need to converted using 'Numbervalue' function.
B28: Data after every pull has to be updated in the respective category tabs. 'Summary' tab is completely formula-driven.
B29: It just needs to be dragged forward every month.
B31: Remember to update 'Gross-up factor' (highlighted in yellow on every tab) as applicable to gross-up ongoing month's volumes.
B33: OEMs combined:
B34: Category | C34: OEM | D34: OEMs combined per Vahan
B35: PV + Electric PV | C35: Tata Motors | D35: TATA MOTORS LTD
D36: TATA MOTORS PASSENGER VEHICLES LTD
D37: TATA PASSENGER ELECTRIC MOBILITY LTD
C38: Kia | D38: KIA MOTORS INDIA PVT LTD
D39: KIA INDIA PRIVATE LIMITED
C40: MG Motor | D40: MG MOTOR INDIA PVT LTD
D41: MG MOTOR INDIA Electric PVT LTD
B42: 2W + Electric 2W | C42: Bajaj Auto | D42: BAJAJ AUTO LTD
D43: CHETAK TECHNOLOGY LIMITED
B44: Electric 2W | C44: Hero Electric | D44: HERO ELECTRIC VEHICLE PVT LTD
D45: HERO ELECTRIC VEHICLES PVT. LTD
B46: 3W | C46: Atul Auto | D46: ATUL AUTO LTD
D47: ATUL GREENTECH PRIVATE LIMITED
C48: Mahindra | D48: MAHINDRA LAST MILE MOBILITY LTD
D49: MAHINDRA & MAHINDRA LIMITED
D50: MAHINDRA REVA ELECTRIC VEHICLES PVT LTD
...

Sheet Summary
B1: 1 | C1: 2 | D1: 3 | E1: =B1 -> 1 | F1: =C1 -> 2 | G1: =D1 -> 3 | H1: =E1 -> 1 | I1: =F1 -> 2 | J1: =G1 -> 3 | K1: =H1 -> 1 | L1: =I1 -> 2 | ... CI1: =CF1 -> 2
B2: ="FY"&RIGHT(B3,2) -> FY19 | C2: ="FY"&RIGHT(C3,2) -> FY19 | D2: ="FY"&RIGHT(D3,2) -> FY19 | E2: ="FY"&RIGHT(E3,2) -> FY20 | F2: ="FY"&RIGHT(F3,2) -> FY20 | G2: ="FY"&RIGHT(G3,2) -> FY20 | H2: ="FY"&RIGHT(H3,2) -> FY20 | I2: ="FY"&RIGHT(I3,2) -> FY20 | ... CI2: ="FY"&RIGHT(CI3,2) -> FY26
B3: =IF(MONTH(B4)<4,CONCATENATE("4Q",MID(YEAR(B4),3,2)),IF(MONTH(B4)<7,CONCATENATE("1Q",MID(YEAR(B4)+1,3,2)),IF(MONTH(B4)<10,CONCATENATE("2Q",MID(YEAR(B4)+1,3,2)),IF(MONTH(B4)<13,CONCATENATE("3Q",MID(YEAR(B4)+1,3,2)),"")))) -> 4Q19 | C3: =IF(MONTH(C4)<4,CONCATENATE("4Q",MID(YEAR(C4),3,2)),IF(MONTH(C4)<7,CONCATENATE("1Q",MID(YEAR(C4)+1,3,2)),IF(MONTH(C4)<10,CONCATENATE("2Q",MID(YEAR(C4)+1,3,2)),IF(MONTH(C4)<13,CONCATENATE("3Q",MID(YEAR(C4)+1,3,2)),"")))) -> 4Q19 | D3: =IF(MONTH(D4)<4,CONCATENATE("4Q",MID(YEAR(D4),3,2)),IF(MONTH(D4)<7,CONCATENATE("1Q",MID(YEAR(D4)+1,3,2)),IF(MONTH(D4)<10,CONCATENATE("2Q",MID(YEAR(D4)+1,3,2)),IF(MONTH(D4)<13,CONCATENATE("3Q",MID(YEAR(D4)+1,3,2)),"")))) -> 4Q19 | E3: =IF(MONTH(E4)<4,CONCATENATE("4Q",MID(YEAR(E4),3,2)),IF(MONTH(E4)<7,CONCATENATE("1Q",MID(YEAR(E4)+1,3,2)),IF(MONTH(E4)<10,CONCATENATE("2Q",MID(YEAR(E4)+1,3,2)),IF(MONTH(E4)<13,CONCATENATE("3Q",MID(YEAR(E4)+1,3,2)),"")))) -> 1Q20 | F3: =IF(MONTH(F4)<4,CONCATENATE("4Q",MID(YEAR(F4),3,2)),IF(MONTH(F4)<7,CONCATENATE("1Q",MID(YEAR(F4)+1,3,2)),IF(MONTH(F4)<10,CONCATENATE("2Q",MID(YEAR(F4)+1,3,2)),IF(MONTH(F4)<13,CONCATENATE("3Q",MID(YEAR(F4)+1,3,2)),"")))) -> 1Q20 | G3: =IF(MONTH(G4)<4,CONCATENATE("4Q",MID(YEAR(G4),3,2)),IF(MONTH(G4)<7,CONCATENATE("1Q",MID(YEAR(G4)+1,3,2)),IF(MONTH(G4)<10,CONCATENATE("2Q",MID(YEAR(G4)+1,3,2)),IF(MONTH(G4)<13,CONCATENATE("3Q",MID(YEAR(G4)+1,3,2)),"")))) -> 1Q20 | H3: =IF(MONTH(H4)<4,CONCATENATE("4Q",MID(YEAR(H4),3,2)),IF(MONTH(H4)<7,CONCATENATE("1Q",MID(YEAR(H4)+1,3,2)),IF(MONTH(H4)<10,CONCATENATE("2Q",MID(YEAR(H4)+1,3,2)),IF(MONTH(H4)<13,CONCATENATE("3Q",MID(YEAR(H4)+1,3,2)),"")))) -> 2Q20 | I3: =IF(MONTH(I4)<4,CONCATENATE("4Q",MID(YEAR(I4),3,2)),IF(MONTH(I4)<7,CONCATENATE("1Q",MID(YEAR(I4)+1,3,2)),IF(MONTH(I4)<10,CONCATENATE("2Q",MID(YEAR(I4)+1,3,2)),IF(MONTH(I4)<13,CONCATENATE("3Q",MID(YEAR(I4)+1,3,2)),"")))) -> 2Q20 | ... CI3: =IF(MONTH(CI4)<4,CONCATENATE("4Q",MID(YEAR(CI4),3,2)),IF(MONTH(CI4)<7,CONCATENATE("1Q",MID(YEAR(CI4)+1,3,2)),IF(MONTH(CI4)<10,CONCATENATE("2Q",MID(YEAR(CI4)+1,3,2)),IF(MONTH(CI4)<13,CONCATENATE("3Q",MID(YEAR(CI4)+1,3,2)),"")))) -> 4Q26 | CL3: QTD | CP3: Like-for-like # months | EC3: QTD | EK3: YTD
A4: Monthly retails | B4: 43466 | C4: =EOMONTH(B4,0)+1 -> 43497 | D4: =EOMONTH(C4,0)+1 -> 43525 | E4: =EOMONTH(D4,0)+1 -> 43556 | F4: =EOMONTH(E4,0)+1 -> 43586 | G4: =EOMONTH(F4,0)+1 -> 43617 | H4: =EOMONTH(G4,0)+1 -> 43647 | I4: =EOMONTH(H4,0)+1 -> 43678 | J4: =EOMONTH(I4,0)+1 -> 43709 | ... CI4: =EOMONTH(CH4,0)+1 -> 46054 | CL4: =_xlfn.XLOOKUP(MAX($C$4:$CK$4),$C$4:$CK$4,$C$3:$CK$3) -> 4Q26 | CM4: {=INDEX($A$3:$CK$3,MATCH($CL$4,$B$3:$CK$3,0)-1)} -> 3Q26 | CN4: =LEFT($CL$4,2)&RIGHT($CL$4,2)-1 -> 4Q25 | CP4: QoQ Change | CQ4: YoY Change | CS4: =CS88 -> Feb-26 vs Feb-25 | CT4: =CT88 -> Feb-26 vs Mar-25 | DB4: 4Q19 | DC4: 1Q20 | DD4: 2Q20 | DE4: 3Q20 | DF4: 4Q20 | DG4: 1Q21 | DH4: 2Q21 | DI4: 3Q21 | DJ4: 4Q21 | DK4: 1Q22 | DL4: 2Q22 | DM4: 3Q22 | DN4: 4Q22 | DO4: 1Q23 | DP4: 2Q23 | DQ4: 3Q23 | DR4: 4Q23 | DS4: 1Q24 | DT4: 2Q24 | DU4: 3Q24 | DV4: 4Q24 | DW4: 1Q25 | DX4: 2Q25 | DY4: 3Q25 | DZ4: 4Q25 | EA4: 1Q26 | EB4: 2Q26 | EC4: 3Q26 | EE4: FY20 | EF4: FY21 | EG4: FY22 | EH4: FY23 | EI4: FY24 | EJ4: FY25 | EK4: FY26
A5: PVs | B5: =B86 -> 318278 | C5: =C86 -> 240146 | D5: =D86 -> 255707 | E5: =E86 -> 246578 | F5: =F86 -> 248684 | G5: =G86 -> 215963 | H5: =H86 -> 222505 | I5: =I86 -> 200559 | ... CI5: =CI86 -> 372215 | CL5: =SUMIFS($C5:$CK5,$C$3:$CK$3,CL$4,$C$1:$CK$1,"<="&_xlfn.XLOOKUP(MAX($C$4:$CK$4),$C$4:$CK$4,$C$1:$CK$1)) -> 886951 | CM5: =SUMIF($A$3:$CK$3,CM$4,$A5:$CK5) -> 1350559 | CN5: =SUMIF($A$3:$CK$3,CN$4,$A5:$CK5) -> 1131997 | CP5: =CL5/SUMIFS($C5:$CK5,$C$3:$CK$3,CM$4,$C$1:$CK$1,"<="&_xlfn.XLOOKUP(MAX($C$4:$CK$4),$C$4:$CK$4,$C$1:$CK$1))-1 -> -0.086632588 | CQ5: =CL5/SUMIFS($C5:$CK5,$C$3:$CK$3,CN$4,$C$1:$CK$1,"<="&_xlfn.XLOOKUP(MAX($C$4:$CK$4),$C$4:$CK$4,$C$1:$CK$1))-1 -> 0.13715895 | DB5: =SUMIF($B$3:$CK$3,DB$4,$B5:$CK5) -> 814131 | DC5: =SUMIF($B$3:$CK$3,DC$4,$B5:$CK5) -> 711225 | DD5: =SUMIF($B$3:$CK$3,DD$4,$B5:$CK5) -> 608280 | DE5: =SUMIF($B$3:$CK$3,DE$4,$B5:$CK5) -> 815772 | DF5: =SUMIF($B$3:$CK$3,DF$4,$B5:$CK5) -> 779858 | DG5: =SUMIF($B$3:$CK$3,DG$4,$B5:$CK5) -> 192171 | DH5: =SUMIF($B$3:$CK$3,DH$4,$B5:$CK5) -> 584207 | DI5: =SUMIF($B$3:$CK$3,DI$4,$B5:$CK5) -> 892442 | ... EC5: =SUMIF($B$3:$CK$3,EC$4,$B5:$CK5) -> 1350559 | EE5: =SUMIF($B$2:$CK$2,EE$4,$B5:$CK5) -> 2915135 | EF5: =SUMIF($B$2:$CK$2,EF$4,$B5:$CK5) -> 2559431 | EG5: =SUMIF($B$2:$CK$2,EG$4,$B5:$CK5) -> 2916189 | EH5: =SUMIF($B$2:$CK$2,EH$4,$B5:$CK5) -> 3594885 | EI5: =SUMIF($B$2:$CK$2,EI$4,$B5:$CK5) -> 3894399 | EJ5: =SUMIF($B$2:$CK$2,EJ$4,$B5:$CK5) -> 4095175 | EK5: =SUMIF($B$2:$CK$2,EK$4,$B5:$CK5) -> 4173548
A6: 2Ws | B6: =B154 -> 1572524 | C6: =C154 -> 1434124 | D6: =D154 -> 1592390 | E6: =E154 -> 1526391 | F6: =F154 -> 1625763 | G6: =G154 -> 1515671 | H6: =H154 -> 1589191 | I6: =I154 -> 1404782 | ... CI6: =CI154 -> 1707438 | CL6: =SUMIFS($C6:$CK6,$C$3:$CK$3,CL$4,$C$1:$CK$1,"<="&_xlfn.XLOOKUP(MAX($C$4:$CK$4),$C$4:$CK$4,$C$1:$CK$1)) -> 3567747 | CM6: =SUMIF($A$3:$CK$3,CM$4,$A6:$CK6) -> 7053801 | CN6: =SUMIF($A$3:$CK$3,CN$4,$A6:$CK6) -> 4419997 | CP6: =CL6/SUMIFS($C6:$CK6,$C$3:$CK$3,CM$4,$C$1:$CK$1,"<="&_xlfn.XLOOKUP(MAX($C$4:$CK$4),$C$4:$CK$4,$C$1:$CK$1))-1 -> -0.37709835 | CQ6: =CL6/SUMIFS($C6:$CK6,$C$3:$CK$3,CN$4,$C$1:$CK$1,"<="&_xlfn.XLOOKUP(MAX($C$4:$CK$4),$C$4:$CK$4,$C$1:$CK$1))-1 -> 0.23119076 | DB6: =SUMIF($B$3:$CK$3,DB$4,$B6:$CK6) -> 4599038 | DC6: =SUMIF($B$3:$CK$3,DC$4,$B6:$CK6) -> 4667825 | DD6: =SUMIF($B$3:$CK$3,DD$4,$B6:$CK6) -> 4275406 | DE6: =SUMIF($B$3:$CK$3,DE$4,$B6:$CK6) -> 5090493 | DF6: =SUMIF($B$3:$CK$3,DF$4,$B6:$CK6) -> 5003019 | DG6: =SUMIF($B$3:$CK$3,DG$4,$B6:$CK6) -> 1518113 | DH6: =SUMIF($B$3:$CK$3,DH$4,$B6:$CK6) -> 3261317 | DI6: =SUMIF($B$3:$CK$3,DI$4,$B6:$CK6) -> 4511578 | ... EC6: =SUMIF($B$3:$CK$3,EC$4,$B6:$CK6) -> 7053801 | EE6: =SUMIF($B$2:$CK$2,EE$4,$B6:$CK6) -> 19036743 | EF6: =SUMIF($B$2:$CK$2,EF$4,$B6:$CK6) -> 13246632 | EG6: =SUMIF($B$2:$CK$2,EG$4,$B6:$CK6) -> 13507221 | EH6: =SUMIF($B$2:$CK$2,EH$4,$B6:$CK6) -> 16033430 | EI6: =SUMIF($B$2:$CK$2,EI$4,$B6:$CK6) -> 17550185 | EJ6: =SUMIF($B$2:$CK$2,EJ$4,$B6:$CK6) -> 18898166 | EK6: =SUMIF($B$2:$CK$2,EK$4,$B6:$CK6) -> 19475797
A7: 3Ws | B7: =B200 -> 53419 | C7: =C200 -> 52447 | D7: =D200 -> 54677 | E7: =E200 -> 46289 | F7: =F200 -> 48953 | G7: =G200 -> 46344 | H7: =H200 -> 55539 | I7: =I200 -> 50312 | ... CI7: =CI200 -> 71616.13 | CL7: =SUMIFS($C7:$CK7,$C$3:$CK$3,CL$4,$C$1:$CK$1,"<="&_xlfn.XLOOKUP(MAX($C$4:$CK$4),$C$4:$CK$4,$C$1:$CK$1)) -> 146538.13 | CM7: =SUMIF($A$3:$CK$3,CM$4,$A7:$CK7) -> 224623 | CN7: =SUMIF($A$3:$CK$3,CN$4,$A7:$CK7) -> 173716 | CP7: =CL7/SUMIFS($C7:$CK7,$C$3:$CK$3,CM$4,$C$1:$CK$1,"<="&_xlfn.XLOOKUP(MAX($C$4:$CK$4),$C$4:$CK$4,$C$1:$CK$1))-1 -> -0.095572046 | CQ7: =CL7/SUMIFS($C7:$CK7,$C$3:$CK$3,CN$4,$C$1:$CK$1,"<="&_xlfn.XLOOKUP(MAX($C$4:$CK$4),$C$4:$CK$4,$C$1:$CK$1))-1 -> 0.24468603 | DB7: =SUMIF($B$3:$CK$3,DB$4,$B7:$CK7) -> 160543 | DC7: =SUMIF($B$3:$CK$3,DC$4,$B7:$CK7) -> 141586 | DD7: =SUMIF($B$3:$CK$3,DD$4,$B7:$CK7) -> 156486 | DE7: =SUMIF($B$3:$CK$3,DE$4,$B7:$CK7) -> 172531 | DF7: =SUMIF($B$3:$CK$3,DF$4,$B7:$CK7) -> 191703 | DG7: =SUMIF($B$3:$CK$3,DG$4,$B7:$CK7) -> 22258 | DH7: =SUMIF($B$3:$CK$3,DH$4,$B7:$CK7) -> 41048 | DI7: =SUMIF($B$3:$CK$3,DI$4,$B7:$CK7) -> 56801 | ... EC7: =SUMIF($B$3:$CK$3,EC$4,$B7:$CK7) -> 224623 | EE7: =SUMIF($B$2:$CK$2,EE$4,$B7:$CK7) -> 662306 | EF7: =SUMIF($B$2:$CK$2,EF$4,$B7:$CK7) -> 194378 | EG7: =SUMIF($B$2:$CK$2,EG$4,$B7:$CK7) -> 242129 | EH7: =SUMIF($B$2:$CK$2,EH$4,$B7:$CK7) -> 405041 | EI7: =SUMIF($B$2:$CK$2,EI$4,$B7:$CK7) -> 634520 | EJ7: =SUMIF($B$2:$CK$2,EJ$4,$B7:$CK7) -> 680350 | EK7: =SUMIF($B$2:$CK$2,EK$4,$B7:$CK7) -> 720967.13
A8: Tractors | B8: =B241 -> 64961 | C8: =C241 -> 56447 | D8: =D241 -> 59993 | E8: =E241 -> 44104 | F8: =F241 -> 46784 | G8: =G241 -> 50291 | H8: =H241 -> 67126 | I8: =I241 -> 62039 | ... CI8: =CI241 -> 86957.13 | CL8: =SUMIFS($C8:$CK8,$C$3:$CK$3,CL$4,$C$1:$CK$1,"<="&_xlfn.XLOOKUP(MAX($C$4:$CK$4),$C$4:$CK$4,$C$1:$CK$1)) -> 199771.13 | CM8: =SUMIF($A$3:$CK$3,CM$4,$A8:$CK8) -> 309683 | CN8: =SUMIF($A$3:$CK$3,CN$4,$A8:$CK8) -> 227729 | CP8: =CL8/SUMIFS($C8:$CK8,$C$3:$CK$3,CM$4,$C$1:$CK$1,"<="&_xlfn.XLOOKUP(MAX($C$4:$CK$4),$C$4:$CK$4,$C$1:$CK$1))-1 -> 0.017288928 | CQ8: =CL8/SUMIFS($C8:$CK8,$C$3:$CK$3,CN$4,$C$1:$CK$1,"<="&_xlfn.XLOOKUP(MAX($C$4:$CK$4),$C$4:$CK$4,$C$1:$CK$1))-1 -> 0.28189071 | DB8: =SUMIF($B$3:$CK$3,DB$4,$B8:$CK8) -> 181401 | DC8: =SUMIF($B$3:$CK$3,DC$4,$B8:$CK8) -> 141179 | DD8: =SUMIF($B$3:$CK$3,DD$4,$B8:$CK8) -> 173211 | DE8: =SUMIF($B$3:$CK$3,DE$4,$B8:$CK8) -> 159043 | DF8: =SUMIF($B$3:$CK$3,DF$4,$B8:$CK8) -> 186192 | DG8: =SUMIF($B$3:$CK$3,DG$4,$B8:$CK8) -> 75845 | DH8: =SUMIF($B$3:$CK$3,DH$4,$B8:$CK8) -> 256081 | DI8: =SUMIF($B$3:$CK$3,DI$4,$B8:$CK8) -> 214202 | ... EC8: =SUMIF($B$3:$CK$3,EC$4,$B8:$CK8) -> 309683 | EE8: =SUMIF($B$2:$CK$2,EE$4,$B8:$CK8) -> 659625 | EF8: =SUMIF($B$2:$CK$2,EF$4,$B8:$CK8) -> 773706 | EG8: =SUMIF($B$2:$CK$2,EG$4,$B8:$CK8) -> 755048 | EH8: =SUMIF($B$2:$CK$2,EH$4,$B8:$CK8) -> 818768 | EI8: =SUMIF($B$2:$CK$2,EI$4,$B8:$CK8) -> 881505 | EJ8: =SUMIF($B$2:$CK$2,EJ$4,$B8:$CK8) -> 869989 | EK8: =SUMIF($B$2:$CK$2,EK$4,$B8:$CK8) -> 950918.13
A9: EV PVs | B9: =B104 -> 74 | C9: =C104 -> 226 | D9: =D104 -> 239 | E9: =E104 -> 115 | F9: =F104 -> 61 | G9: =G104 -> 57 | H9: =H104 -> 109 | I9: =I104 -> 96 | ... CI9: =CI104 -> 13026.043 | CL9: =SUMIFS($C9:$CK9,$C$3:$CK$3,CL$4,$C$1:$CK$1,"<="&_xlfn.XLOOKUP(MAX($C$4:$CK$4),$C$4:$CK$4,$C$1:$CK$1)) -> 32009.043 | CM9: =SUMIF($A$3:$CK$3,CM$4,$A9:$CK9) -> 50461 | CN9: =SUMIF($A$3:$CK$3,CN$4,$A9:$CK9) -> 34530 | CP9: =CL9/SUMIFS($C9:$CK9,$C$3:$CK$3,CM$4,$C$1:$CK$1,"<="&_xlfn.XLOOKUP(MAX($C$4:$CK$4),$C$4:$CK$4,$C$1:$CK$1))-1 -> -0.08117681 | CQ9: =CL9/SUMIFS($C9:$CK9,$C$3:$CK$3,CN$4,$C$1:$CK$1,"<="&_xlfn.XLOOKUP(MAX($C$4:$CK$4),$C$4:$CK$4,$C$1:$CK$1))-1 -> 0.50256037 | DB9: =SUMIF($B$3:$CK$3,DB$4,$B9:$CK9) -> 539 | DC9: =SUMIF($B$3:$CK$3,DC$4,$B9:$CK9) -> 233 | DD9: =SUMIF($B$3:$CK$3,DD$4,$B9:$CK9) -> 367 | DE9: =SUMIF($B$3:$CK$3,DE$4,$B9:$CK9) -> 509 | DF9: =SUMIF($B$3:$CK$3,DF$4,$B9:$CK9) -> 1193 | DG9: =SUMIF($B$3:$CK$3,DG$4,$B9:$CK9) -> 381 | DH9: =SUMIF($B$3:$CK$3,DH$4,$B9:$CK9) -> 1063 | DI9: =SUMIF($B$3:$CK$3,DI$4,$B9:$CK9) -> 1549 | ... EC9: =SUMIF($B$3:$CK$3,EC$4,$B9:$CK9) -> 50461 | EE9: =SUMIF($B$2:$CK$2,EE$4,$B9:$CK9) -> 2302 | EF9: =SUMIF($B$2:$CK$2,EF$4,$B9:$CK9) -> 5133 | EG9: =SUMIF($B$2:$CK$2,EG$4,$B9:$CK9) -> 18553 | EH9: =SUMIF($B$2:$CK$2,EH$4,$B9:$CK9) -> 47301 | EI9: =SUMIF($B$2:$CK$2,EI$4,$B9:$CK9) -> 90910 | EJ9: =SUMIF($B$2:$CK$2,EJ$4,$B9:$CK9) -> 107589 | EK9: =SUMIF($B$2:$CK$2,EK$4,$B9:$CK9) -> 174531.04
A10: EV 2Ws | B10: =B178 -> 2745 | C10: =C178 -> 3123 | D10: =D178 -> 5868 | E10: =E178 -> 3076 | F10: =F178 -> 1668 | G10: =G178 -> 1757 | H10: =H178 -> 1569 | I10: =I178 -> 1506 | ... CI10: =CI178 -> 108773.96 | CL10: =SUMIFS($C10:$CK10,$C$3:$CK$3,CL$4,$C$1:$CK$1,"<="&_xlfn.XLOOKUP(MAX($C$4:$CK$4),$C$4:$CK$4,$C$1:$CK$1)) -> 232056.96 | CM10: =SUMIF($A$3:$CK$3,CM$4,$A10:$CK10) -> 360803 | CN10: =SUMIF($A$3:$CK$3,CN$4,$A10:$CK10) -> 306565 | CP10: =CL10/SUMIFS($C10:$CK10,$C$3:$CK$3,CM$4,$C$1:$CK$1,"<="&_xlfn.XLOOKUP(MAX($C$4:$CK$4),$C$4:$CK$4,$C$1:$CK$1))-1 -> -0.11713048 | CQ10: =CL10/SUMIFS($C10:$CK10,$C$3:$CK$3,CN$4,$C$1:$CK$1,"<="&_xlfn.XLOOKUP(MAX($C$4:$CK$4),$C$4:$CK$4,$C$1:$CK$1))-1 -> 0.3250176 | DB10: =SUMIF($B$3:$CK$3,DB$4,$B10:$CK10) -> 11736 | DC10: =SUMIF($B$3:$CK$3,DC$4,$B10:$CK10) -> 6501 | DD10: =SUMIF($B$3:$CK$3,DD$4,$B10:$CK10) -> 4633 | DE10: =SUMIF($B$3:$CK$3,DE$4,$B10:$CK10) -> 7519 | DF10: =SUMIF($B$3:$CK$3,DF$4,$B10:$CK10) -> 8177 | DG10: =SUMIF($B$3:$CK$3,DG$4,$B10:$CK10) -> 2154 | DH10: =SUMIF($B$3:$CK$3,DH$4,$B10:$CK10) -> 6692 | DI10: =SUMIF($B$3:$CK$3,DI$4,$B10:$CK10) -> 12088 | ... EC10: =SUMIF($B$3:$CK$3,EC$4,$B10:$CK10) -> 360803 | EE10: =SUMIF($B$2:$CK$2,EE$4,$B10:$CK10) -> 26830 | EF10: =SUMIF($B$2:$CK$2,EF$4,$B10:$CK10) -> 44799 | EG10: =SUMIF($B$2:$CK$2,EG$4,$B10:$CK10) -> 252554 | EH10: =SUMIF($B$2:$CK$2,EH$4,$B10:$CK10) -> 727817 | EI10: =SUMIF($B$2:$CK$2,EI$4,$B10:$CK10) -> 948371 | EJ10: =SUMIF($B$2:$CK$2,EJ$4,$B10:$CK10) -> 1149956 | EK10: =SUMIF($B$2:$CK$2,EK$4,$B10:$CK10) -> 1206213
A11: EV 3Ws | B11: =B219 -> 79 | C11: =C219 -> 67 | D11: =D219 -> 121 | E11: =E219 -> 44 | F11: =F219 -> 66 | G11: =G219 -> 111 | H11: =H219 -> 63 | I11: =I219 -> 121 | ... CI11: =CI219 -> 22013.522 | CL11: =SUMIFS($C11:$CK11,$C$3:$CK$3,CL$4,$C$1:$CK$1,"<="&_xlfn.XLOOKUP(MAX($C$4:$CK$4),$C$4:$CK$4,$C$1:$CK$1)) -> 45642.522 | CM11: =SUMIF($A$3:$CK$3,CM$4,$A11:$CK11) -> 76162 | CN11: =SUMIF($A$3:$CK$3,CN$4,$A11:$CK11) -> 45906 | CP11: =CL11/SUMIFS($C11:$CK11,$C$3:$CK$3,CM$4,$C$1:$CK$1,"<="&_xlfn.XLOOKUP(MAX($C$4:$CK$4),$C$4:$CK$4,$C$1:$CK$1))-1 -> -0.13830007 | CQ11: =CL11/SUMIFS($C11:$CK11,$C$3:$CK$3,CN$4,$C$1:$CK$1,"<="&_xlfn.XLOOKUP(MAX($C$4:$CK$4),$C$4:$CK$4,$C$1:$CK$1))-1 -> 0.5371993 | DB11: =SUMIF($B$3:$CK$3,DB$4,$B11:$CK11) -> 267 | DC11: =SUMIF($B$3:$CK$3,DC$4,$B11:$CK11) -> 221 | DD11: =SUMIF($B$3:$CK$3,DD$4,$B11:$CK11) -> 360 | DE11: =SUMIF($B$3:$CK$3,DE$4,$B11:$CK11) -> 470 | DF11: =SUMIF($B$3:$CK$3,DF$4,$B11:$CK11) -> 741 | DG11: =SUMIF($B$3:$CK$3,DG$4,$B11:$CK11) -> 144 | DH11: =SUMIF($B$3:$CK$3,DH$4,$B11:$CK11) -> 431 | DI11: =SUMIF($B$3:$CK$3,DI$4,$B11:$CK11) -> 621 | ... EC11: =SUMIF($B$3:$CK$3,EC$4,$B11:$CK11) -> 76162 | EE11: =SUMIF($B$2:$CK$2,EE$4,$B11:$CK11) -> 1792 | EF11: =SUMIF($B$2:$CK$2,EF$4,$B11:$CK11) -> 2429 | EG11: =SUMIF($B$2:$CK$2,EG$4,$B11:$CK11) -> 11278 | EH11: =SUMIF($B$2:$CK$2,EH$4,$B11:$CK11) -> 30849 | EI11: =SUMIF($B$2:$CK$2,EI$4,$B11:$CK11) -> 101412 | EJ11: =SUMIF($B$2:$CK$2,EJ$4,$B11:$CK11) -> 159246 | EK11: =SUMIF($B$2:$CK$2,EK$4,$B11:$CK11) -> 236479.52
A12: CNG PVs | B12: =B120 -> 24100 | C12: =C120 -> 19106 | D12: =D120 -> 17600 | E12: =E120 -> 19880 | F12: =F120 -> 20529 | G12: =G120 -> 16817 | H12: =H120 -> 18187 | I12: =I120 -> 16635 | ... CI12: =CI120 -> 87677.087 | CL12: =SUMIFS($C12:$CK12,$C$3:$CK$3,CL$4,$C$1:$CK$1,"<="&_xlfn.XLOOKUP(MAX($C$4:$CK$4),$C$4:$CK$4,$C$1:$CK$1)) -> 205544.09 | CM12: =SUMIF($A$3:$CK$3,CM$4,$A12:$CK12) -> 295367 | CN12: =SUMIF($A$3:$CK$3,CN$4,$A12:$CK12) -> 239719 | CP12: =CL12/SUMIFS($C12:$CK12,$C$3:$CK$3,CM$4,$C$1:$CK$1,"<="&_xlfn.XLOOKUP(MAX($C$4:$CK$4),$C$4:$CK$4,$C$1:$CK$1))-1 -> -0.045335283 | CQ12: =CL12/SUMIFS($C12:$CK12,$C$3:$CK$3,CN$4,$C$1:$CK$1,"<="&_xlfn.XLOOKUP(MAX($C$4:$CK$4),$C$4:$CK$4,$C$1:$CK$1))-1 -> 0.23315847 | DB12: =SUMIF($B$3:$CK$3,DB$4,$B12:$CK12) -> 60806 | DC12: =SUMIF($B$3:$CK$3,DC$4,$B12:$CK12) -> 57226 | DD12: =SUMIF($B$3:$CK$3,DD$4,$B12:$CK12) -> 48358 | DE12: =SUMIF($B$3:$CK$3,DE$4,$B12:$CK12) -> 63116 | DF12: =SUMIF($B$3:$CK$3,DF$4,$B12:$CK12) -> 58106 | DG12: =SUMIF($B$3:$CK$3,DG$4,$B12:$CK12) -> 10808 | DH12: =SUMIF($B$3:$CK$3,DH$4,$B12:$CK12) -> 43557 | DI12: =SUMIF($B$3:$CK$3,DI$4,$B12:$CK12) -> 67046 | ... EC12: =SUMIF($B$3:$CK$3,EC$4,$B12:$CK12) -> 295367 | EE12: =SUMIF($B$2:$CK$2,EE$4,$B12:$CK12) -> 226806 | EF12: =SUMIF($B$2:$CK$2,EF$4,$B12:$CK12) -> 199984 | EG12: =SUMIF($B$2:$CK$2,EG$4,$B12:$CK12) -> 268803 | EH12: =SUMIF($B$2:$CK$2,EH$4,$B12:$CK12) -> 408993 | EI12: =SUMIF($B$2:$CK$2,EI$4,$B12:$CK12) -> 593125 | EJ12: =SUMIF($B$2:$CK$2,EJ$4,$B12:$CK12) -> 786686 | EK12: =SUMIF($B$2:$CK$2,EK$4,$B12:$CK12) -> 904751.09
A13: Strong Hybrid PVs | B13: =B136 -> 0 | C13: =C136 -> 0 | D13: =D136 -> 0 | E13: =E136 -> 0 | F13: =F136 -> 0 | G13: =G136 -> 0 | H13: =H136 -> 0 | I13: =I136 -> 0 | ... CI13: =CI136 -> 8262.4783 | CL13: =SUMIFS($C13:$CK13,$C$3:$CK$3,CL$4,$C$1:$CK$1,"<="&_xlfn.XLOOKUP(MAX($C$4:$CK$4),$C$4:$CK$4,$C$1:$CK$1)) -> 19541.478 | CM13: =SUMIF($A$3:$CK$3,CM$4,$A13:$CK13) -> 28337 | CN13: =SUMIF($A$3:$CK$3,CN$4,$A13:$CK13) -> 25750 | CP13: =CL13/SUMIFS($C13:$CK13,$C$3:$CK$3,CM$4,$C$1:$CK$1,"<="&_xlfn.XLOOKUP(MAX($C$4:$CK$4),$C$4:$CK$4,$C$1:$CK$1))-1 -> -0.025022289 | CQ13: =IFERROR(CL13/SUMIFS($C13:$CK13,$C$3:$CK$3,CN$4,$C$1:$CK$1,"<="&_xlfn.XLOOKUP(MAX($C$4:$CK$4),$C$4:$CK$4,$C$1:$CK$1))-1,"NA") -> 0.16415336 | DB13: =SUMIF($B$3:$CK$3,DB$4,$B13:$CK13) -> 0 | DC13: =SUMIF($B$3:$CK$3,DC$4,$B13:$CK13) -> 0 | DD13: =SUMIF($B$3:$CK$3,DD$4,$B13:$CK13) -> 0 | DE13: =SUMIF($B$3:$CK$3,DE$4,$B13:$CK13) -> 0 | DF13: =SUMIF($B$3:$CK$3,DF$4,$B13:$CK13) -> 0 | DG13: =SUMIF($B$3:$CK$3,DG$4,$B13:$CK13) -> 0 | DH13: =SUMIF($B$3:$CK$3,DH$4,$B13:$CK13) -> 0 | DI13: =SUMIF($B$3:$CK$3,DI$4,$B13:$CK13) -> 0 | ... EC13: =SUMIF($B$3:$CK$3,EC$4,$B13:$CK13) -> 28337 | EE13: =SUMIF($B$2:$CK$2,EE$4,$B13:$CK13) -> 0 | EF13: =SUMIF($B$2:$CK$2,EF$4,$B13:$CK13) -> 0 | EG13: =SUMIF($B$2:$CK$2,EG$4,$B13:$CK13) -> 0 | EH13: =SUMIF($B$2:$CK$2,EH$4,$B13:$CK13) -> 0 | EI13: =SUMIF($B$2:$CK$2,EI$4,$B13:$CK13) -> 1638 | EJ13: =SUMIF($B$2:$CK$2,EJ$4,$B13:$CK13) -> 80528 | EK13: =SUMIF($B$2:$CK$2,EK$4,$B13:$CK13) -> 99950.478
A14: CVs | B14: =CV!C28 -> 95632 | C14: =CV!D28 -> 91966 | D14: =CV!E28 -> 97277 | E14: =CV!F28 -> 86799 | F14: =CV!G28 -> 83074 | G14: =CV!H28 -> 71738 | H14: =CV!I28 -> 78553 | I14: =CV!J28 -> 70272 | ... BR14: =CV!BS28 -> 72082 | BS14: =CV!BU28 -> 80972 | BT14: =CV!BU28 -> 80972 | BU14: =CV!BV28 -> 70649 | BV14: =CV!BW28 -> 96005 | BW14: =CV!BX28 -> 79473 | BX14: =CV!BY28 -> 89333 | BY14: =CV!BZ28 -> 84364 | BZ14: =CV!CA28 -> 76643 | CA14: =CV!CB28 -> 74712 | ... CI14: =CV!CJ28 -> 101845.48 | CL14: =SUMIFS($C14:$CK14,$C$3:$CK$3,CL$4,$C$1:$CK$1,"<="&_xlfn.XLOOKUP(MAX($C$4:$CK$4),$C$4:$CK$4,$C$1:$CK$1)) -> 213287.48 | CM14: =SUMIF($A$3:$CK$3,CM$4,$A14:$CK14) -> 297914 | CN14: =SUMIF($A$3:$CK$3,CN$4,$A14:$CK14) -> 264811 | CP14: =CL14/SUMIFS($C14:$CK14,$C$3:$CK$3,CM$4,$C$1:$CK$1,"<="&_xlfn.XLOOKUP(MAX($C$4:$CK$4),$C$4:$CK$4,$C$1:$CK$1))-1 -> 0.01543223 | CQ14: =CL14/SUMIFS($C14:$CK14,$C$3:$CK$3,CN$4,$C$1:$CK$1,"<="&_xlfn.XLOOKUP(MAX($C$4:$CK$4),$C$4:$CK$4,$C$1:$CK$1))-1 -> 0.21546563 | DB14: =SUMIF($B$3:$CK$3,DB$4,$B14:$CK14) -> 284875 | DC14: =SUMIF($B$3:$CK$3,DC$4,$B14:$CK14) -> 241611 | DD14: =SUMIF($B$3:$CK$3,DD$4,$B14:$CK14) -> 216843 | DE14: =SUMIF($B$3:$CK$3,DE$4,$B14:$CK14) -> 232728 | DF14: =SUMIF($B$3:$CK$3,DF$4,$B14:$CK14) -> 313558 | DG14: =SUMIF($B$3:$CK$3,DG$4,$B14:$CK14) -> 44856 | DH14: =SUMIF($B$3:$CK$3,DH$4,$B14:$CK14) -> 121120 | DI14: =SUMIF($B$3:$CK$3,DI$4,$B14:$CK14) -> 181523 | ... EC14: =SUMIF($B$3:$CK$3,EC$4,$B14:$CK14) -> 297914 | EE14: =SUMIF($B$2:$CK$2,EE$4,$B14:$CK14) -> 1004740 | EF14: =SUMIF($B$2:$CK$2,EF$4,$B14:$CK14) -> 568655 | EG14: =SUMIF($B$2:$CK$2,EG$4,$B14:$CK14) -> 729115 | EH14: =SUMIF($B$2:$CK$2,EH$4,$B14:$CK14) -> 963233 | EI14: =SUMIF($B$2:$CK$2,EI$4,$B14:$CK14) -> 987985 | EJ14: =SUMIF($B$2:$CK$2,EJ$4,$B14:$CK14) -> 953056 | EK14: =SUMIF($B$2:$CK$2,EK$4,$B14:$CK14) -> 975572.48
A15: LCVs | B15: =CV!C14 -> 59172 | C15: =CV!D14 -> 56146 | D15: =CV!E14 -> 58150 | E15: =CV!F14 -> 51259 | F15: =CV!G14 -> 50819 | G15: =CV!H14 -> 45214 | H15: =CV!I14 -> 51213 | I15: =CV!J14 -> 46214 | ... BR15: =CV!BS14 -> 43578 | BS15: =CV!BU14 -> 51519 | BT15: =CV!BU14 -> 51519 | BU15: =CV!BV14 -> 43793 | BV15: =CV!BW14 -> 59510 | BW15: =CV!BX14 -> 47605 | BX15: =CV!BY14 -> 53274 | BY15: =CV!BZ14 -> 45534 | BZ15: =CV!CA14 -> 44987 | CA15: =CV!CB14 -> 45398 | ... CI15: =CV!CJ14 -> 58383.304 | CL15: =SUMIFS($C15:$CK15,$C$3:$CK$3,CL$4,$C$1:$CK$1,"<="&_xlfn.XLOOKUP(MAX($C$4:$CK$4),$C$4:$CK$4,$C$1:$CK$1)) -> 127816.3 | CM15: =SUMIF($A$3:$CK$3,CM$4,$A15:$CK15) -> 192039 | CN15: =SUMIF($A$3:$CK$3,CN$4,$A15:$CK15) -> 160389 | CP15: =CL15/SUMIFS($C15:$CK15,$C$3:$CK$3,CM$4,$C$1:$CK$1,"<="&_xlfn.XLOOKUP(MAX($C$4:$CK$4),$C$4:$CK$4,$C$1:$CK$1))-1 -> -0.078243374 | CQ15: =CL15/SUMIFS($C15:$CK15,$C$3:$CK$3,CN$4,$C$1:$CK$1,"<="&_xlfn.XLOOKUP(MAX($C$4:$CK$4),$C$4:$CK$4,$C$1:$CK$1))-1 -> 0.19326242 | DB15: =SUMIF($B$3:$CK$3,DB$4,$B15:$CK15) -> 173468 | DC15: =SUMIF($B$3:$CK$3,DC$4,$B15:$CK15) -> 147292 | DD15: =SUMIF($B$3:$CK$3,DD$4,$B15:$CK15) -> 143290 | DE15: =SUMIF($B$3:$CK$3,DE$4,$B15:$CK15) -> 165137 | DF15: =SUMIF($B$3:$CK$3,DF$4,$B15:$CK15) -> 210535 | DG15: =SUMIF($B$3:$CK$3,DG$4,$B15:$CK15) -> 36511 | DH15: =SUMIF($B$3:$CK$3,DH$4,$B15:$CK15) -> 107735 | DI15: =SUMIF($B$3:$CK$3,DI$4,$B15:$CK15) -> 143944 | ... EC15: =SUMIF($B$3:$CK$3,EC$4,$B15:$CK15) -> 192039 | EE15: =SUMIF($B$2:$CK$2,EE$4,$B15:$CK15) -> 666254 | EF15: =SUMIF($B$2:$CK$2,EF$4,$B15:$CK15) -> 442269 | EG15: =SUMIF($B$2:$CK$2,EG$4,$B15:$CK15) -> 492621 | EH15: =SUMIF($B$2:$CK$2,EH$4,$B15:$CK15) -> 611607 | EI15: =SUMIF($B$2:$CK$2,EI$4,$B15:$CK15) -> 598965 | EJ15: =SUMIF($B$2:$CK$2,EJ$4,$B15:$CK15) -> 577205 | EK15: =SUMIF($B$2:$CK$2,EK$4,$B15:$CK15) -> 595364.3
A17: y/y | CI17: Last 4 week growth
A18: =A5 -> PVs | N18: =N5/B5-1 -> -0.026407732 | O18: =O5/C5-1 -> 0.0087571727 | P18: =P5/D5-1 -> -0.10938692 | Q18: =Q5/E5-1 -> -0.90205533 | R18: =R5/F5-1 -> -0.86922359 | S18: =S5/G5-1 -> -0.37258697 | T18: =T5/H5-1 -> -0.22740163 | U18: =U5/I5-1 -> -0.018174203 | ... CH18: =CH5/BV5-1 -> 0.087652719 | CI18: ='PV Weekly trends'!EP1 -> 0.29774427 | CL18: =CL5/SUMIFS($C5:$CK5,$C$3:$CK$3,CN$4,$C$1:$CK$1,"<="&_xlfn.XLOOKUP(MAX($C$4:$CK$4),$C$4:$CK$4,$C$1:$CK$1))-1 -> 0.13715895 | DF18: =DF5/DB5-1 -> -0.042097648 | DG18: =DG5/DC5-1 -> -0.72980281 | DH18: =DH5/DD5-1 -> -0.039575524 | DI18: =DI5/DE5-1 -> 0.093984594 | DJ18: =DJ5/DF5-1 -> 0.14201688 | DK18: =DK5/DG5-1 -> 1.6907494 | DL18: =DL5/DH5-1 -> 0.38437403 | DM18: =DM5/DI5-1 -> -0.14117556 | ... EC18: =EC5/DY5-1 -> 0.21644804 | EF18: =EF5/EE5-1 -> -0.12201973 | EG18: =EG5/EF5-1 -> 0.13938958 | EH18: =EH5/EG5-1 -> 0.23273389 | EI18: =EI5/EH5-1 -> 0.083316712 | EJ18: =EJ5/EI5-1 -> 0.051555067 | EK18: =EK5/EJ5-1 -> 0.019137888
A19: =A6 -> 2Ws | N19: =N6/B6-1 -> -0.07413305 | O19: =O6/C6-1 -> 0.027429288 | P19: =P6/D6-1 -> 0.30219984 | Q19: =Q6/E6-1 -> -0.72813781 | R19: =R6/F6-1 -> -0.88179335 | S19: =S6/G6-1 -> -0.39896653 | T19: =T6/H6-1 -> -0.36142226 | U19: =U6/I6-1 -> -0.2421543 | ... CH19: =CH6/BV6-1 -> 0.21182585 | CI19: ='2W Weekly trends'!EP1 -> 0.30247111 | CL19: =CL6/SUMIFS($C6:$CK6,$C$3:$CK$3,CN$4,$C$1:$CK$1,"<="&_xlfn.XLOOKUP(MAX($C$4:$CK$4),$C$4:$CK$4,$C$1:$CK$1))-1 -> 0.23119076 | DF19: =DF6/DB6-1 -> 0.087840327 | DG19: =DG6/DC6-1 -> -0.6747708 | DH19: =DH6/DD6-1 -> -0.23719127 | DI19: =DI6/DE6-1 -> -0.11372474 | DJ19: =DJ6/DF6-1 -> -0.20935259 | DK19: =DK6/DG6-1 -> 0.64161561 | DL19: =DL6/DH6-1 -> 0.051125972 | DM19: =DM6/DI6-1 -> -0.10458602 | ... EC19: =EC6/DY6-1 -> 0.19569527 | EF19: =EF6/EE6-1 -> -0.3041545 | EG19: =EG6/EF6-1 -> 0.019672095 | EH19: =EH6/EG6-1 -> 0.18702655 | EI19: =EI6/EH6-1 -> 0.094599534 | EJ19: =EJ6/EI6-1 -> 0.076807225 | EK19: =EK6/EJ6-1 -> 0.030565455
A20: =A9 -> EV PVs | N20: =N9/B9-1 -> 2.8918919 | O20: =O9/C9-1 -> 1.1725664 | P20: =P9/D9-1 -> 0.73221757 | Q20: =Q9/E9-1 -> -0.97391304 | R20: =R9/F9-1 -> 0.36065574 | S20: =S9/G9-1 -> 4.1754386 | T20: =T9/H9-1 -> 2.2752294 | U20: =U9/I9-1 -> 2.8541667 | ... CH20: =CH9/BV9-1 -> 0.59628322 | CI20: ='Electric PV Weekly trends'!EP1 -> 0.61516854 | CL20: =CL9/SUMIFS($C9:$CK9,$C$3:$CK$3,CN$4,$C$1:$CK$1,"<="&_xlfn.XLOOKUP(MAX($C$4:$CK$4),$C$4:$CK$4,$C$1:$CK$1))-1 -> 0.50256037 | DF20: =DF9/DB9-1 -> 1.2133581 | DG20: =DG9/DC9-1 -> 0.63519313 | DH20: =DH9/DD9-1 -> 1.8964578 | DI20: =DI9/DE9-1 -> 2.043222 | DJ20: =DJ9/DF9-1 -> 0.79379715 | DK20: =DK9/DG9-1 -> 3.4540682 | DL20: =DL9/DH9-1 -> 2.3264346 | DM20: =DM9/DI9-1 -> 2.6197547 | ... EC20: =EC9/DY9-1 -> 0.72764311 | EF20: =EF9/EE9-1 -> 1.2298002 | EG20: =EG9/EF9-1 -> 2.6144555 | EH20: =EH9/EG9-1 -> 1.5495068 | EI20: =EI9/EH9-1 -> 0.92194668 | EJ20: =EJ9/EI9-1 -> 0.18346717 | EK20: =EK9/EJ9-1 -> 0.62220156
A21: =A10 -> EV 2Ws | N21: =N10/B10-1 -> 0.07140255 | O21: =O10/C10-1 -> -0.2465578 | P21: =P10/D10-1 -> -0.50869121 | Q21: =Q10/E10-1 -> -0.97236671 | R21: =R10/F10-1 -> -0.66546763 | S21: =S10/G10-1 -> -0.14001138 | T21: =T10/H10-1 -> -0.051625239 | U21: =U10/I10-1 -> 0.40438247 | ... CH21: =CH10/BV10-1 -> 0.25258324 | CI21: ='Electric 2W Weekly trends'!EP1 -> 0.38737683 | CL21: =CL10/SUMIFS($C10:$CK10,$C$3:$CK$3,CN$4,$C$1:$CK$1,"<="&_xlfn.XLOOKUP(MAX($C$4:$CK$4),$C$4:$CK$4,$C$1:$CK$1))-1 -> 0.3250176 | DF21: =DF10/DB10-1 -> -0.30325494 | DG21: =DG10/DC10-1 -> -0.66866636 | DH21: =DH10/DD10-1 -> 0.44442046 | DI21: =DI10/DE10-1 -> 0.60766059 | DJ21: =DJ10/DF10-1 -> 1.918552 | DK21: =DK10/DG10-1 -> 4.3871866 | DL21: =DL10/DH10-1 -> 6.2851166 | DM21: =DM10/DI10-1 -> 4.9539212 | ... EC21: =EC10/DY10-1 -> 0.082673172 | EF21: =EF10/EE10-1 -> 0.66973537 | EG21: =EG10/EF10-1 -> 4.6374919 | EH21: =EH10/EG10-1 -> 1.8818273 | EI21: =EI10/EH10-1 -> 0.30303497 | EJ21: =EJ10/EI10-1 -> 0.21255922 | EK21: =EK10/EJ10-1 -> 0.048920964
A22: =A11 -> EV 3Ws | N22: =N11/B11-1 -> 2.3417722 | O22: =O11/C11-1 -> 2.5820896 | P22: =P11/D11-1 -> 0.95867769 | Q22: =Q11/E11-1 -> -0.52272727 | R22: =R11/F11-1 -> -0.31818182 | S22: =S11/G11-1 -> -0.2972973 | T22: =T11/H11-1 -> 0.79365079 | U22: =U11/I11-1 -> 0.44628099 | ... CI22: =CI11/BW11-1 -> 0.53447105 | CL22: =CL11/SUMIFS($C11:$CK11,$C$3:$CK$3,CN$4,$C$1:$CK$1,"<="&_xlfn.XLOOKUP(MAX($C$4:$CK$4),$C$4:$CK$4,$C$1:$CK$1))-1 -> 0.5371993 | DF22: =DF11/DB11-1 -> 1.7752809 | DG22: =DG11/DC11-1 -> -0.34841629 | DH22: =DH11/DD11-1 -> 0.19722222 | DI22: =DI11/DE11-1 -> 0.3212766 | DJ22: =DJ11/DF11-1 -> 0.66396761 | DK22: =DK11/DG11-1 -> 4.6597222 | DL22: =DL11/DH11-1 -> 5.2993039 | DM22: =DM11/DI11-1 -> 4.4750403 | ... EC22: =EC11/DY11-1 -> 0.59886638 | EF22: =EF11/EE11-1 -> 0.35546875 | EG22: =EG11/EF11-1 -> 3.643063 | EH22: =EH11/EG11-1 -> 1.7353254 | EI22: =EI11/EH11-1 -> 2.2873675 | EJ22: =EJ11/EI11-1 -> 0.57028754 | EK22: =EK11/EJ11-1 -> 0.48499505
A23: =A12 -> CNG PVs | N23: =N12/B12-1 -> 0.093858921 | O23: =O12/C12-1 -> -0.08081231 | P23: =P12/D12-1 -> -0.19420455 | Q23: =Q12/E12-1 -> -0.95352113 | R23: =R12/F12-1 -> -0.9293195 | S23: =S12/G12-1 -> -0.49854314 | T23: =T12/H12-1 -> -0.31758949 | U23: =U12/I12-1 -> -0.056086564 | ... CI23: =CI12/BW12-1 -> 0.41127848 | CL23: =CL12/SUMIFS($C12:$CK12,$C$3:$CK$3,CN$4,$C$1:$CK$1,"<="&_xlfn.XLOOKUP(MAX($C$4:$CK$4),$C$4:$CK$4,$C$1:$CK$1))-1 -> 0.23315847 | DF23: =DF12/DB12-1 -> -0.044403513 | DG23: =DG12/DC12-1 -> -0.8111348 | DH23: =DH12/DD12-1 -> -0.099280367 | DI23: =DI12/DE12-1 -> 0.062266303 | DJ23: =DJ12/DF12-1 -> 0.35223557 | DK23: =DK12/DG12-1 -> 2.8458549 | DL23: =DL12/DH12-1 -> 0.71423652 | DM23: =DM12/DI12-1 -> -0.16085971 | ... EC23: =EC12/DY12-1 -> 0.39101625 | EF23: =EF12/EE12-1 -> -0.11825966 | EG23: =EG12/EF12-1 -> 0.34412253 | EH23: =EH12/EG12-1 -> 0.52153436 | EI23: =EI12/EH12-1 -> 0.45020819 | EJ23: =EJ12/EI12-1 -> 0.32634099 | EK23: =EK12/EJ12-1 -> 0.15007905
A24: =A13 -> Strong Hybrid PVs | N24: =IFERROR(N13/B13-1,"NA") -> NA | O24: =IFERROR(O13/C13-1,"NA") -> NA | P24: =IFERROR(P13/D13-1,"NA") -> NA | Q24: =IFERROR(Q13/E13-1,"NA") -> NA | R24: =IFERROR(R13/F13-1,"NA") -> NA | S24: =IFERROR(S13/G13-1,"NA") -> NA | T24: =IFERROR(T13/H13-1,"NA") -> NA | U24: =IFERROR(U13/I13-1,"NA") -> NA | ... CI24: =IFERROR(CI13/BW13-1,"NA") -> 0.11010053 | CL24: NA | DF24: =IFERROR(DF13/DB13-1,"NA") -> NA | DG24: =IFERROR(DG13/DC13-1,"NA") -> NA | DH24: =IFERROR(DH13/DD13-1,"NA") -> NA | DI24: =IFERROR(DI13/DE13-1,"NA") -> NA | DJ24: =IFERROR(DJ13/DF13-1,"NA") -> NA | DK24: =IFERROR(DK13/DG13-1,"NA") -> NA | DL24: =IFERROR(DL13/DH13-1,"NA") -> NA | DM24: =IFERROR(DM13/DI13-1,"NA") -> NA | ... EC24: =IFERROR(EC13/DY13-1,"NA") -> 0.228039 | EF24: =IFERROR(EF13/EE13-1,"NA") -> NA | EG24: =IFERROR(EG13/EF13-1,"NA") -> NA | EH24: =IFERROR(EH13/EG13-1,"NA") -> NA | EI24: =IFERROR(EI13/EH13-1,"NA") -> NA | EJ24: =IFERROR(EJ13/EI13-1,"NA") -> 48.162393 | EK24: =IFERROR(EK13/EJ13-1,"NA") -> 0.24118913
CI25: yoy growth
A26: =A7 -> 3Ws | N26: =N7/B7-1 -> 0.078211872 | O26: =O7/C7-1 -> 0.14586154 | P26: =P7/D7-1 -> 0.35356731 | Q26: =Q7/E7-1 -> -0.73127525 | R26: =R7/F7-1 -> -0.9703389 | S26: =S7/G7-1 -> -0.81945883 | T26: =T7/H7-1 -> -0.81333837 | U26: =U7/I7-1 -> -0.7571951 | ... CI26: =CI7/BW7-1 -> 0.29341034 | CL26: =CL7/SUMIFS($C7:$CK7,$C$3:$CK$3,CN$4,$C$1:$CK$1,"<="&_xlfn.XLOOKUP(MAX($C$4:$CK$4),$C$4:$CK$4,$C$1:$CK$1))-1 -> 0.24468603 | DF26: =DF7/DB7-1 -> 0.1940913 | DG26: =DG7/DC7-1 -> -0.84279519 | DH26: =DH7/DD7-1 -> -0.73768899 | DI26: =DI7/DE7-1 -> -0.67077801 | DJ26: =DJ7/DF7-1 -> -0.61257257 | DK26: =DK7/DG7-1 -> 0.31462845 | DL26: =DL7/DH7-1 -> 0.50993958 | DM26: =DM7/DI7-1 -> 0.31451911 | ... EC26: =EC7/DY7-1 -> 0.23089189 | EF26: =EF7/EE7-1 -> -0.7065133 | EG26: =EG7/EF7-1 -> 0.24566052 | EH26: =EH7/EG7-1 -> 0.67283142 | EI26: =EI7/EH7-1 -> 0.56655746 | EJ26: =EJ7/EI7-1 -> 0.072227826 | EK26: =EK7/EJ7-1 -> 0.059700346
A27: =A8 -> Tractors | N27: =N8/B8-1 -> 0.021551392 | O27: =O8/C8-1 -> 0.061668468 | P27: =P8/D8-1 -> -0.001500175 | Q27: =Q8/E8-1 -> -0.85602213 | R27: =R8/F8-1 -> -0.74106532 | S27: =S8/G8-1 -> 0.1409795 | T27: =T8/H8-1 -> 0.39160683 | U27: =U8/I8-1 -> 0.30397008 | ... CI27: =CI8/BW8-1 -> 0.36225981 | CL27: =CL8/SUMIFS($C8:$CK8,$C$3:$CK$3,CN$4,$C$1:$CK$1,"<="&_xlfn.XLOOKUP(MAX($C$4:$CK$4),$C$4:$CK$4,$C$1:$CK$1))-1 -> 0.28189071 | DF27: =DF8/DB8-1 -> 0.0264111 | DG27: =DG8/DC8-1 -> -0.46277421 | DH27: =DH8/DD8-1 -> 0.47843382 | DI27: =DI8/DE8-1 -> 0.34681816 | DJ27: =DJ8/DF8-1 -> 0.22227593 | DK27: =DK8/DG8-1 -> 0.65350386 | DL27: =DL8/DH8-1 -> -0.050702707 | DM27: =DM8/DI8-1 -> -0.1432573 | ... EC27: =EC8/DY8-1 -> 0.28351646 | EF27: =EF8/EE8-1 -> 0.17294827 | EG27: =EG8/EF8-1 -> -0.024115103 | EH27: =EH8/EG8-1 -> 0.084391986 | EI27: =EI8/EH8-1 -> 0.076623659 | EJ27: =EJ8/EI8-1 -> -0.013064021 | EK27: =EK8/EJ8-1 -> 0.093023165
A28: =A14 -> CVs | N28: =N14/B14-1 -> -0.08605906 | O28: =O14/C14-1 -> 0.065861297 | P28: =P14/D14-1 -> 0.31719728 | Q28: =Q14/E14-1 -> -0.75154092 | R28: =R14/F14-1 -> -0.96448949 | S28: =S14/G14-1 -> -0.71646826 | T28: =T14/H14-1 -> -0.60910468 | U28: =U14/I14-1 -> -0.46419627 | ... CI28: =CI14/BW14-1 -> 0.28151043 | CL28: =CL14/SUMIFS($C14:$CK14,$C$3:$CK$3,CN$4,$C$1:$CK$1,"<="&_xlfn.XLOOKUP(MAX($C$4:$CK$4),$C$4:$CK$4,$C$1:$CK$1))-1 -> 0.21546563 | DF28: =DF14/DB14-1 -> 0.10068627 | DG28: =DG14/DC14-1 -> -0.8143462 | DH28: =DH14/DD14-1 -> -0.4414392 | DI28: =DI14/DE14-1 -> -0.2200208 | DJ28: =DJ14/DF14-1 -> -0.2946887 | DK28: =DK14/DG14-1 -> 1.6567683 | DL28: =DL14/DH14-1 -> 0.51744551 | DM28: =DM14/DI14-1 -> 0.072404048 | ... EC28: =EC14/DY14-1 -> 0.2808382 | EF28: =EF14/EE14-1 -> -0.43402771 | EG28: =EG14/EF14-1 -> 0.2821746 | EH28: =EH14/EG14-1 -> 0.32109887 | EI28: =EI14/EH14-1 -> 0.025696794 | EJ28: =EJ14/EI14-1 -> -0.035353776 | EK28: =EK14/EJ14-1 -> 0.023625556
A29: =A15 -> LCVs | N29: =N15/B15-1 -> 0.042452511 | O29: =O15/C15-1 -> 0.18368183 | P29: =P15/D15-1 -> 0.41688736 | Q29: =Q15/E15-1 -> -0.7236973 | R29: =R15/F15-1 -> -0.9447254 | S29: =S15/G15-1 -> -0.56785509 | T29: =T15/H15-1 -> -0.44014215 | U29: =U15/I15-1 -> -0.26535249 | ... CI29: =CI15/BW15-1 -> 0.22641118 | CL29: =CL15/SUMIFS($C15:$CK15,$C$3:$CK$3,CN$4,$C$1:$CK$1,"<="&_xlfn.XLOOKUP(MAX($C$4:$CK$4),$C$4:$CK$4,$C$1:$CK$1))-1 -> 0.19326242 | DF29: =DF15/DB15-1 -> 0.21368206 | DG29: =DG15/DC15-1 -> -0.75211824 | DH29: =DH15/DD15-1 -> -0.24813316 | DI29: =DI15/DE15-1 -> -0.12833587 | DJ29: =DJ15/DF15-1 -> -0.26815494 | DK29: =DK15/DG15-1 -> 1.1232505 | DL29: =DL15/DH15-1 -> 0.22539565 | DM29: =DM15/DI15-1 -> -0.074362252 | ... EC29: =EC15/DY15-1 -> 0.30789139 | EF29: =EF15/EE15-1 -> -0.3361856 | EG29: =EG15/EF15-1 -> 0.11384926 | EH29: =EH15/EG15-1 -> 0.2415366 | EI29: =EI15/EH15-1 -> -0.020670136 | EJ29: =EJ15/EI15-1 -> -0.036329335 | EK29: =EK15/EJ15-1 -> 0.031460754
A31: EV share in retails
A32: PVs | B32: =B9/B5 -> 0.00023250115 | C32: =C9/C5 -> 0.00094109417 | D32: =D9/D5 -> 0.0009346635 | E32: =E9/E5 -> 0.00046638386 | F32: =F9/F5 -> 0.00024529121 | G32: =G9/G5 -> 0.0002639341 | H32: =H9/H5 -> 0.00048987663 | I32: =I9/I5 -> 0.00047866214 | ... CI32: =CI9/CI5 -> 0.03499602 | CL32: =CL9/CL5 -> 0.036088852 | CM32: =CM9/CM5 -> 0.037363047 | CN32: =CN9/CN5 -> 0.030503614 | CP32: =ROUND((CL32-CM32)*10000,0)&" bps" -> -13 bps | CQ32: =ROUND((CL32-CN32)*10000,0)&" bps" -> 56 bps | DB32: =DB9/DB5 -> 0.00066205562 | DC32: =DC9/DC5 -> 0.00032760378 | DD32: =DD9/DD5 -> 0.00060334057 | DE32: =DE9/DE5 -> 0.00062394885 | DF32: =DF9/DF5 -> 0.0015297657 | DG32: =DG9/DG5 -> 0.0019826092 | DH32: =DH9/DH5 -> 0.0018195605 | DI32: =DI9/DI5 -> 0.001735687 | ... EC32: =EC9/EC5 -> 0.037363047 | EE32: =EE9/EE5 -> 0.00078967183 | EF32: =EF9/EF5 -> 0.0020055239 | EG32: =EG9/EG5 -> 0.0063620705 | EH32: =EH9/EH5 -> 0.013157862 | EI32: =EI9/EI5 -> 0.023343782 | EJ32: =EJ9/EJ5 -> 0.026272137 | EK32: =EK9/EK5 -> 0.041818387
A33: 2Ws | B33: =B10/B6 -> 0.0017456013 | C33: =C10/C6 -> 0.002177636 | D33: =D10/D6 -> 0.0036850269 | E33: =E10/E6 -> 0.002015211 | F33: =F10/F6 -> 0.0010259798 | G33: =G10/G6 -> 0.0011592225 | H33: =H10/H6 -> 0.00098729479 | I33: =I10/I6 -> 0.0010720525 | ... CI33: =CI10/CI6 -> 0.063705946 | CL33: =CL10/CL6 -> 0.065042996 | CM33: =CM10/CM6 -> 0.051150153 | CN33: =CN10/CN6 -> 0.069358644 | CP33: =ROUND((CL33-CM33)*10000,0)&" bps" -> 139 bps | CQ33: =ROUND((CL33-CN33)*10000,0)&" bps" -> -43 bps | DB33: =DB10/DB6 -> 0.002551838 | DC33: =DC10/DC6 -> 0.0013927257 | DD33: =DD10/DD6 -> 0.0010836398 | DE33: =DE10/DE6 -> 0.0014770672 | DF33: =DF10/DF6 -> 0.0016344131 | DG33: =DG10/DG6 -> 0.0014188667 | DH33: =DH10/DH6 -> 0.0020519318 | DI33: =DI10/DI6 -> 0.0026793286 | ... EC33: =EC10/EC6 -> 0.051150153 | EE33: =EE10/EE6 -> 0.0014093797 | EF33: =EF10/EF6 -> 0.0033819162 | EG33: =EG10/EG6 -> 0.018697703 | EH33: =EH10/EH6 -> 0.045393718 | EI33: =EI10/EI6 -> 0.054037664 | EJ33: =EJ10/EJ6 -> 0.060850138 | EK33: =EK10/EK6 -> 0.061933946
A34: 3Ws | B34: =B11/B7 -> 0.0014788746 | C34: =C11/C7 -> 0.0012774801 | D34: =D11/D7 -> 0.0022129963 | E34: =E11/E7 -> 0.00095054981 | F34: =F11/F7 -> 0.001348232 | G34: =G11/G7 -> 0.0023951321 | H34: =H11/H7 -> 0.001134338 | I34: =I11/I7 -> 0.0024049928 | ... CI34: =CI11/CI7 -> 0.30738217 | CL34: =CL11/CL7 -> 0.31147198 | CM34: =CM11/CM7 -> 0.3390659 | CN34: =CN11/CN7 -> 0.26425891 | CP34: =ROUND((CL34-CM34)*10000,0)&" bps" -> -276 bps | CQ34: =ROUND((CL34-CN34)*10000,0)&" bps" -> 472 bps | DB34: =DB11/DB7 -> 0.0016631058 | DC34: =DC11/DC7 -> 0.0015608888 | DD34: =DD11/DD7 -> 0.0023005253 | DE34: =DE11/DE7 -> 0.0027241481 | DF34: =DF11/DF7 -> 0.0038653542 | DG34: =DG11/DG7 -> 0.006469584 | DH34: =DH11/DH7 -> 0.010499903 | DI34: =DI11/DI7 -> 0.010932906 | ... EC34: =EC11/EC7 -> 0.3390659 | EE34: =EE11/EE7 -> 0.002705698 | EF34: =EF11/EF7 -> 0.01249627 | EG34: =EG11/EG7 -> 0.046578477 | EH34: =EH11/EH7 -> 0.07616266 | EI34: =EI11/EI7 -> 0.15982475 | EJ34: =EJ11/EJ7 -> 0.23406482 | EK34: =EK11/EK7 -> 0.32800319
A36: CNG PV Penetration | B36: =B12/B5 -> 0.075719968 | C36: =C12/C5 -> 0.079559934 | D36: =D12/D5 -> 0.068828777 | E36: =E12/E5 -> 0.080623576 | F36: =F12/F5 -> 0.082550546 | G36: =G12/G5 -> 0.07786982 | H36: =H12/H5 -> 0.081737489 | I36: =I12/I5 -> 0.082943174 | ... CI36: =CI12/CI5 -> 0.23555495 | CL36: =CL12/CL5 -> 0.23174233 | CM36: =CM12/CM5 -> 0.21869981 | CN36: =CN12/CN5 -> 0.21176646 | CP36: =ROUND((CL36-CM36)*10000,0)&" bps" -> 130 bps | CQ36: =ROUND((CL36-CN36)*10000,0)&" bps" -> 200 bps | DB36: =DB12/DB5 -> 0.074688226 | DC36: =DC12/DC5 -> 0.080461176 | DD36: =DD12/DD5 -> 0.079499573 | DE36: =DE12/DE5 -> 0.077369657 | DF36: =DF12/DF5 -> 0.074508436 | DG36: =DG12/DG5 -> 0.056241577 | DH36: =DH12/DH5 -> 0.074557477 | DI36: =DI12/DI5 -> 0.075126451 | ... EC36: =EC12/EC5 -> 0.21869981 | EE36: =EE12/EE5 -> 0.077802915 | EF36: =EF12/EF5 -> 0.078136117 | EG36: =EG12/EG5 -> 0.092176124 | EH36: =EH12/EH5 -> 0.11377082 | EI36: =EI12/EI5 -> 0.15230206 | EJ36: =EJ12/EJ5 -> 0.1921007 | EK36: =EK12/EK5 -> 0.21678224
A37: Strong Hybrids PV Penetration | B37: =B13/B5 -> 0 | C37: =C13/C5 -> 0 | D37: =D13/D5 -> 0 | E37: =E13/E5 -> 0 | F37: =F13/F5 -> 0 | G37: =G13/G5 -> 0 | H37: =H13/H5 -> 0 | I37: =I13/I5 -> 0 | ... CI37: =CI13/CI5 -> 0.022198134 | CL37: =CL13/CL5 -> 0.022032196 | CM37: =CM13/CM5 -> 0.020981682 | CN37: =CN13/CN5 -> 0.02274741 | CP37: =ROUND((CL37-CM37)*10000,0)&" bps" -> 11 bps | CQ37: =ROUND((CL37-CN37)*10000,0)&" bps" -> -7 bps | DB37: =DB13/DB5 -> 0 | DC37: =DC13/DC5 -> 0 | DD37: =DD13/DD5 -> 0 | DE37: =DE13/DE5 -> 0 | DF37: =DF13/DF5 -> 0 | DG37: =DG13/DG5 -> 0 | DH37: =DH13/DH5 -> 0 | DI37: =DI13/DI5 -> 0 | ... EC37: =EC13/EC5 -> 0.020981682 | EE37: =EE13/EE5 -> 0 | EF37: =EF13/EF5 -> 0 | EG37: =EG13/EG5 -> 0 | EH37: =EH13/EH5 -> 0 | EI37: =EI13/EI5 -> 0.00042060405 | EJ37: =EJ13/EJ5 -> 0.019664117 | EK37: =EK13/EK5 -> 0.023948563
A39: Company wise | B39: =B4 -> 43466 | C39: =C4 -> 43497 | D39: =D4 -> 43525 | E39: =E4 -> 43556 | F39: =F4 -> 43586 | G39: =G4 -> 43617 | H39: =H4 -> 43647 | I39: =I4 -> 43678 | ... CI39: =CI4 -> 46054 | CL39: =CL4 -> 4Q26 | CM39: =CM4 -> 3Q26 | CN39: =CN4 -> 4Q25 | CP39: =CP4 -> QoQ Change | CQ39: =CQ4 -> YoY Change
A40: Maruti (only PV) | B40: =B78 -> 159587 | C40: =C78 -> 118284 | D40: =D78 -> 127156 | E40: =E78 -> 120832 | F40: =F78 -> 123329 | G40: =G78 -> 104852 | H40: =H78 -> 104948 | I40: =I78 -> 93963 | ... CI40: =CI78 -> 148873.39 | CL40: =SUMIFS($C40:$CK40,$C$3:$CK$3,CL$4,$C$1:$CK$1,"<="&_xlfn.XLOOKUP(MAX($C$4:$CK$4),$C$4:$CK$4,$C$1:$CK$1)) -> 366640.39 | CM40: =SUMIF($A$3:$CK$3,CM$4,$A40:$CK40) -> 552741 | CN40: =SUMIF($A$3:$CK$3,CN$4,$A40:$CK40) -> 468360 | CP40: =CL40/SUMIFS($C40:$CK40,$C$3:$CK$3,CM$4,$C$1:$CK$1,"<="&_xlfn.XLOOKUP(MAX($C$4:$CK$4),$C$4:$CK$4,$C$1:$CK$1))-1 -> -0.085589036 | CQ40: =CL40/SUMIFS($C40:$CK40,$C$3:$CK$3,CN$4,$C$1:$CK$1,"<="&_xlfn.XLOOKUP(MAX($C$4:$CK$4),$C$4:$CK$4,$C$1:$CK$1))-1 -> 0.09728221 | DB40: =SUMIF($B$3:$CK$3,DB$4,$B40:$CK40) -> 405027 | DC40: =SUMIF($B$3:$CK$3,DC$4,$B40:$CK40) -> 349013 | DD40: =SUMIF($B$3:$CK$3,DD$4,$B40:$CK40) -> 287494 | DE40: =SUMIF($B$3:$CK$3,DE$4,$B40:$CK40) -> 392510 | DF40: =SUMIF($B$3:$CK$3,DF$4,$B40:$CK40) -> 380834 | DG40: =SUMIF($B$3:$CK$3,DG$4,$B40:$CK40) -> 95809 | DH40: =SUMIF($B$3:$CK$3,DH$4,$B40:$CK40) -> 288743 | DI40: =SUMIF($B$3:$CK$3,DI$4,$B40:$CK40) -> 434388 | ... EC40: =SUMIF($B$3:$CK$3,EC$4,$B40:$CK40) -> 552741 | EE40: =SUMIF($B$2:$CK$2,EE$4,$B40:$CK40) -> 1409851 | EF40: =SUMIF($B$2:$CK$2,EF$4,$B40:$CK40) -> 1236632 | EG40: =SUMIF($B$2:$CK$2,EG$4,$B40:$CK40) -> 1242295 | EH40: =SUMIF($B$2:$CK$2,EH$4,$B40:$CK40) -> 1480871 | EI40: =SUMIF($B$2:$CK$2,EI$4,$B40:$CK40) -> 1604623 | EJ40: =SUMIF($B$2:$CK$2,EJ$4,$B40:$CK40) -> 1670504 | EK40: =SUMIF($B$2:$CK$2,EK$4,$B40:$CK40) -> 1684806.4
A42: Hyundai | B42: =B80 -> 54730 | C42: =C80 -> 40556 | D42: =D80 -> 38926 | E42: =E80 -> 37939 | F42: =F80 -> 40223 | G42: =G80 -> 38787 | H42: =H80 -> 42210 | I42: =I80 -> 38903 | ... CI42: =CI80 -> 44578.043 | CL42: =SUMIFS($C42:$CK42,$C$3:$CK$3,CL$4,$C$1:$CK$1,"<="&_xlfn.XLOOKUP(MAX($C$4:$CK$4),$C$4:$CK$4,$C$1:$CK$1)) -> 111356.04 | CM42: =SUMIF($A$3:$CK$3,CM$4,$A42:$CK42) -> 167050 | CN42: =SUMIF($A$3:$CK$3,CN$4,$A42:$CK42) -> 144718 | CP42: =CL42/SUMIFS($C42:$CK42,$C$3:$CK$3,CM$4,$C$1:$CK$1,"<="&_xlfn.XLOOKUP(MAX($C$4:$CK$4),$C$4:$CK$4,$C$1:$CK$1))-1 -> -0.055824627 | CQ42: =CL42/SUMIFS($C42:$CK42,$C$3:$CK$3,CN$4,$C$1:$CK$1,"<="&_xlfn.XLOOKUP(MAX($C$4:$CK$4),$C$4:$CK$4,$C$1:$CK$1))-1 -> 0.10501864 | DB42: =SUMIF($B$3:$CK$3,DB$4,$B42:$CK42) -> 134212 | DC42: =SUMIF($B$3:$CK$3,DC$4,$B42:$CK42) -> 116949 | DD42: =SUMIF($B$3:$CK$3,DD$4,$B42:$CK42) -> 115109 | DE42: =SUMIF($B$3:$CK$3,DE$4,$B42:$CK42) -> 147748 | DF42: =SUMIF($B$3:$CK$3,DF$4,$B42:$CK42) -> 125001 | DG42: =SUMIF($B$3:$CK$3,DG$4,$B42:$CK42) -> 35702 | DH42: =SUMIF($B$3:$CK$3,DH$4,$B42:$CK42) -> 111372 | DI42: =SUMIF($B$3:$CK$3,DI$4,$B42:$CK42) -> 151938 | ... EC42: =SUMIF($B$3:$CK$3,EC$4,$B42:$CK42) -> 167050 | EE42: =SUMIF($B$2:$CK$2,EE$4,$B42:$CK42) -> 504807 | EF42: =SUMIF($B$2:$CK$2,EF$4,$B42:$CK42) -> 453023 | EG42: =SUMIF($B$2:$CK$2,EG$4,$B42:$CK42) -> 478673 | EH42: =SUMIF($B$2:$CK$2,EH$4,$B42:$CK42) -> 526452 | EI42: =SUMIF($B$2:$CK$2,EI$4,$B42:$CK42) -> 562176 | EJ42: =SUMIF($B$2:$CK$2,EJ$4,$B42:$CK42) -> 559528 | EK42: =SUMIF($B$2:$CK$2,EK$4,$B42:$CK42) -> 526485.04
A44: Kia | B44: =B81 -> 0 | C44: =C81 -> 0 | D44: =D81 -> 0 | E44: =E81 -> 0 | F44: =F81 -> 0 | G44: =G81 -> 1 | H44: =H81 -> 0 | I44: =I81 -> 159 | ... CI44: =CI81 -> 24608.391 | CL44: =SUMIFS($C44:$CK44,$C$3:$CK$3,CL$4,$C$1:$CK$1,"<="&_xlfn.XLOOKUP(MAX($C$4:$CK$4),$C$4:$CK$4,$C$1:$CK$1)) -> 55154.391 | CM44: =SUMIF($A$3:$CK$3,CM$4,$A44:$CK44) -> 79531 | CN44: =SUMIF($A$3:$CK$3,CN$4,$A44:$CK44) -> 65181 | CP44: =CL44/SUMIFS($C44:$CK44,$C$3:$CK$3,CM$4,$C$1:$CK$1,"<="&_xlfn.XLOOKUP(MAX($C$4:$CK$4),$C$4:$CK$4,$C$1:$CK$1))-1 -> -0.05841315 | CQ44: =CL44/SUMIFS($C44:$CK44,$C$3:$CK$3,CN$4,$C$1:$CK$1,"<="&_xlfn.XLOOKUP(MAX($C$4:$CK$4),$C$4:$CK$4,$C$1:$CK$1))-1 -> 0.30182433 | DB44: =SUMIF($B$3:$CK$3,DB$4,$B44:$CK44) -> 0 | DC44: =SUMIF($B$3:$CK$3,DC$4,$B44:$CK44) -> 1 | DD44: =SUMIF($B$3:$CK$3,DD$4,$B44:$CK44) -> 3242 | DE44: =SUMIF($B$3:$CK$3,DE$4,$B44:$CK44) -> 29773 | DF44: =SUMIF($B$3:$CK$3,DF$4,$B44:$CK44) -> 29818 | DG44: =SUMIF($B$3:$CK$3,DG$4,$B44:$CK44) -> 8124 | DH44: =SUMIF($B$3:$CK$3,DH$4,$B44:$CK44) -> 23414 | DI44: =SUMIF($B$3:$CK$3,DI$4,$B44:$CK44) -> 53967 | ... EC44: =SUMIF($B$3:$CK$3,EC$4,$B44:$CK44) -> 79531 | EE44: =SUMIF($B$2:$CK$2,EE$4,$B44:$CK44) -> 62834 | EF44: =SUMIF($B$2:$CK$2,EF$4,$B44:$CK44) -> 131361 | EG44: =SUMIF($B$2:$CK$2,EG$4,$B44:$CK44) -> 155871 | EH44: =SUMIF($B$2:$CK$2,EH$4,$B44:$CK44) -> 233082 | EI44: =SUMIF($B$2:$CK$2,EI$4,$B44:$CK44) -> 226032 | EJ44: =SUMIF($B$2:$CK$2,EJ$4,$B44:$CK44) -> 242085 | EK44: =SUMIF($B$2:$CK$2,EK$4,$B44:$CK44) -> 249336.39
A46: Toyota | B46: =B84 -> 12854 | C46: =C84 -> 9604 | D46: =D84 -> 10281 | E46: =E84 -> 9759 | F46: =F84 -> 9874 | G46: =G84 -> 9075 | H46: =H84 -> 9982 | I46: =I84 -> 9325 | ... CI46: =CI84 -> 25381.304 | CL46: =SUMIFS($C46:$CK46,$C$3:$CK$3,CL$4,$C$1:$CK$1,"<="&_xlfn.XLOOKUP(MAX($C$4:$CK$4),$C$4:$CK$4,$C$1:$CK$1)) -> 60741.304 | CM46: =SUMIF($A$3:$CK$3,CM$4,$A46:$CK46) -> 91149 | CN46: =SUMIF($A$3:$CK$3,CN$4,$A46:$CK46) -> 75593 | CP46: =CL46/SUMIFS($C46:$CK46,$C$3:$CK$3,CM$4,$C$1:$CK$1,"<="&_xlfn.XLOOKUP(MAX($C$4:$CK$4),$C$4:$CK$4,$C$1:$CK$1))-1 -> -0.061519022 | CQ46: =CL46/SUMIFS($C46:$CK46,$C$3:$CK$3,CN$4,$C$1:$CK$1,"<="&_xlfn.XLOOKUP(MAX($C$4:$CK$4),$C$4:$CK$4,$C$1:$CK$1))-1 -> 0.18035959 | DB46: =SUMIF($B$3:$CK$3,DB$4,$B46:$CK46) -> 32739 | DC46: =SUMIF($B$3:$CK$3,DC$4,$B46:$CK46) -> 28708 | DD46: =SUMIF($B$3:$CK$3,DD$4,$B46:$CK46) -> 27389 | DE46: =SUMIF($B$3:$CK$3,DE$4,$B46:$CK46) -> 29670 | DF46: =SUMIF($B$3:$CK$3,DF$4,$B46:$CK46) -> 23165 | DG46: =SUMIF($B$3:$CK$3,DG$4,$B46:$CK46) -> 6484 | DH46: =SUMIF($B$3:$CK$3,DH$4,$B46:$CK46) -> 14857 | DI46: =SUMIF($B$3:$CK$3,DI$4,$B46:$CK46) -> 24861 | ... EC46: =SUMIF($B$3:$CK$3,EC$4,$B46:$CK46) -> 91149 | EE46: =SUMIF($B$2:$CK$2,EE$4,$B46:$CK46) -> 108932 | EF46: =SUMIF($B$2:$CK$2,EF$4,$B46:$CK46) -> 78853 | EG46: =SUMIF($B$2:$CK$2,EG$4,$B46:$CK46) -> 112449 | EH46: =SUMIF($B$2:$CK$2,EH$4,$B46:$CK46) -> 155367 | EI46: =SUMIF($B$2:$CK$2,EI$4,$B46:$CK46) -> 200286 | EJ46: =SUMIF($B$2:$CK$2,EJ$4,$B46:$CK46) -> 264387 | EK46: =SUMIF($B$2:$CK$2,EK$4,$B46:$CK46) -> 296287.3
A48: PV | B48: =B82 -> 20436 | C48: =C82 -> 18711 | D48: =D82 -> 21785 | E48: =E82 -> 20696 | F48: =F82 -> 20877 | G48: =G82 -> 17912 | H48: =H82 -> 17651 | I48: =I82 -> 14329 | ... CI48: =CI82 -> 50964.348 | CL48: =SUMIFS($C48:$CK48,$C$3:$CK$3,CL$4,$C$1:$CK$1,"<="&_xlfn.XLOOKUP(MAX($C$4:$CK$4),$C$4:$CK$4,$C$1:$CK$1)) -> 115054.35 | CM48: =SUMIF($A$3:$CK$3,CM$4,$A48:$CK48) -> 175981 | CN48: =SUMIF($A$3:$CK$3,CN$4,$A48:$CK48) -> 144364 | CP48: =CL48/SUMIFS($C48:$CK48,$C$3:$CK$3,CM$4,$C$1:$CK$1,"<="&_xlfn.XLOOKUP(MAX($C$4:$CK$4),$C$4:$CK$4,$C$1:$CK$1))-1 -> -0.097060572 | CQ48: =CL48/SUMIFS($C48:$CK48,$C$3:$CK$3,CN$4,$C$1:$CK$1,"<="&_xlfn.XLOOKUP(MAX($C$4:$CK$4),$C$4:$CK$4,$C$1:$CK$1))-1 -> 0.20039592 | DB48: =SUMIF($B$3:$CK$3,DB$4,$B48:$CK48) -> 60932 | DC48: =SUMIF($B$3:$CK$3,DC$4,$B48:$CK48) -> 59485 | DD48: =SUMIF($B$3:$CK$3,DD$4,$B48:$CK48) -> 43874 | DE48: =SUMIF($B$3:$CK$3,DE$4,$B48:$CK48) -> 49637 | DF48: =SUMIF($B$3:$CK$3,DF$4,$B48:$CK48) -> 56359 | DG48: =SUMIF($B$3:$CK$3,DG$4,$B48:$CK48) -> 8932 | DH48: =SUMIF($B$3:$CK$3,DH$4,$B48:$CK48) -> 29434 | DI48: =SUMIF($B$3:$CK$3,DI$4,$B48:$CK48) -> 46506 | ... EC48: =SUMIF($B$3:$CK$3,EC$4,$B48:$CK48) -> 175981 | EE48: =SUMIF($B$2:$CK$2,EE$4,$B48:$CK48) -> 209355 | EF48: =SUMIF($B$2:$CK$2,EF$4,$B48:$CK48) -> 132824 | EG48: =SUMIF($B$2:$CK$2,EG$4,$B48:$CK48) -> 194005 | EH48: =SUMIF($B$2:$CK$2,EH$4,$B48:$CK48) -> 320363 | EI48: =SUMIF($B$2:$CK$2,EI$4,$B48:$CK48) -> 422613 | EJ48: =SUMIF($B$2:$CK$2,EJ$4,$B48:$CK48) -> 508027 | EK48: =SUMIF($B$2:$CK$2,EK$4,$B48:$CK48) -> 557270.35
...

Sheet Text_Summary
A1: =Summary!A158 & " mkt share in " & TEXT(Summary!BW$4,"MMmM") & " at " & TEXT(Summary!CI158,"0.0%") & " vs " & TEXT(Summary!CH158,"0.0%") & " in " & TEXT(Summary!CH$4,"mmmm YYYY") & " & " & TEXT(Summary!BW158,"0.0%") & " in " & TEXT(Summary!BW$4,"mmmm yyy") -> Hero MotoCorp mkt share in February at 26.8% vs 26.5% in January 2026 & 28.4% in February 2025
A2: =Summary!A159 & " mkt share in " & TEXT(Summary!BW$4,"MMmM") & " at " & TEXT(Summary!CI159,"0.0%") & " vs " & TEXT(Summary!CH159,"0.0%") & " in " & TEXT(Summary!CH$4,"mmmm YYYY") & " & " & TEXT(Summary!BW159,"0.0%") & " in " & TEXT(Summary!BW$4,"mmmm yyy") -> Honda mkt share in February at 25.4% vs 25.5% in January 2026 & 24.2% in February 2025
A3: =Summary!A163 & " mkt share in " & TEXT(Summary!BW$4,"MMmM") & " at " & TEXT(Summary!CI163,"0.0%") & " vs " & TEXT(Summary!CH163,"0.0%") & " in " & TEXT(Summary!CH$4,"mmmm YYYY") & " & " & TEXT(Summary!BW163,"0.0%") & " in " & TEXT(Summary!BW$4,"mmmm yyy") -> TVS mkt share in February at 20.1% vs 19.7% in January 2026 & 18.8% in February 2025
A4: =_xlfn.CONCAT(Summary!A187," / ",Summary!A183," / ", Summary!A186, " E2W mkt share at ", TEXT(Summary!CI187,"0.0%")," / ", TEXT(Summary!CI183,"0.0%")," / ", TEXT(Summary!CI186,"0.0%")," in ", TEXT(Summary!CI4,"mmmm")," vs ", TEXT(Summary!CH187,"0.0%")," / ", TEXT(Summary!CH183,"0.0%")," / ", TEXT(Summary!CH186,"0.0%")," in ",TEXT(Summary!CH4,"mmmm yyy")," & ",TEXT(Summary!BW187,"0.0%")," / ", TEXT(Summary!BW183,"0.0%")," / ", TEXT(Summary!BW186,"0.0%")," in ",TEXT(Summary!BW4,"mmmm yyy")) -> TVS Motor / Bajaj Auto / Ola Electric E2W mkt share at 29.2% / 22.6% / 4.0% in February vs 28.2% / 20.8% / 6.1% in January 2026 & 24.7% / 28.1% / 11.3% in February 2025
A5: =Summary!A182 & " mkt share in " & TEXT(Summary!BW$4,"MMmM") & " at " & TEXT(Summary!CI182,"0.0%") & " vs " & TEXT(Summary!CH182,"0.0%") & " in " & TEXT(Summary!CH$4,"mmmm YYYY") & " & " & TEXT(Summary!BW182,"0.0%") & " in " & TEXT(Summary!BW$4,"mmmm yyy") -> Ather Energy mkt share in February at 18.4% vs 17.9% in January 2026 & 15.6% in February 2025
A6: =Summary!A89 & " PV mkt share in " & TEXT(Summary!BW$4,"MMmM") & " at " & TEXT(Summary!CI89,"0.0%") & " vs " & TEXT(Summary!CH89,"0.0%") & " in " & TEXT(Summary!CH$4,"mmmm YYYY") & " & " & TEXT(Summary!BW89,"0.0%") & " in " & TEXT(Summary!BW$4,"mmmm yyy") -> Maruti PV mkt share in February at 40.0% vs 42.3% in January 2026 & 39.1% in February 2025
A7: =Summary!A91 & " PV mkt share in " & TEXT(Summary!BW$4,"MMmM") & " at " & TEXT(Summary!CI91,"0.0%") & " vs " & TEXT(Summary!CH91,"0.0%") & " in " & TEXT(Summary!CH$4,"mmmm YYYY") & " & " & TEXT(Summary!BW91,"0.0%") & " in " & TEXT(Summary!BW$4,"mmmm yyy") -> Hyundai PV mkt share in February at 12.0% vs 13.0% in January 2026 & 12.8% in February 2025
A8: =Summary!A93 & " PV mkt share in " & TEXT(Summary!BW$4,"MMmM") & " at " & TEXT(Summary!CI93,"0.0%") & " vs " & TEXT(Summary!CH93,"0.0%") & " in " & TEXT(Summary!CH$4,"mmmm YYYY") & " & " & TEXT(Summary!BW93,"0.0%") & " in " & TEXT(Summary!BW$4,"mmmm yyy") -> M&M PV mkt share in February at 13.7% vs 12.5% in January 2026 & 13.6% in February 2025
A9: =Summary!A109 & " EV mkt share in " & TEXT(Summary!BW$4,"MMmM") & " at " & TEXT(Summary!CI109,"0.0%") & " vs " & TEXT(Summary!CH109,"0.0%") & " in " & TEXT(Summary!CH$4,"mmmm YYYY") & " & " & TEXT(Summary!BW109,"0.0%") & " in " & TEXT(Summary!BW$4,"mmmm yyy") -> Mahindra EV mkt share in February at 20.6% vs 20.0% in January 2026 & 5.4% in February 2025
A10: =Summary!A32 & " EV penetration in " & TEXT(Summary!BW$4,"MMmM") & " at " & TEXT(Summary!CI32,"0.0%") & " vs " & TEXT(Summary!CH32,"0.0%") & " in " & TEXT(Summary!CH$4,"mmmm YYYY") & " & " & TEXT(Summary!BW32,"0.0%") & " in " & TEXT(Summary!BW$4,"mmmm yyy") -> PVs EV penetration in February at 3.5% vs 3.7% in January 2026 & 3.1% in February 2025
A11: =Summary!A33 & " EV penetration in " & TEXT(Summary!BW$4,"MMmM") & " at " & TEXT(Summary!CI33,"0.0%") & " vs " & TEXT(Summary!CH33,"0.0%") & " in " & TEXT(Summary!CH$4,"mmmm YYYY") & " & " & TEXT(Summary!BW33,"0.0%") & " in " & TEXT(Summary!BW$4,"mmmm yyy") -> 2Ws EV penetration in February at 6.4% vs 6.6% in January 2026 & 5.6% in February 2025
A12: =Summary!A34 & " EV penetration in " & TEXT(Summary!BW$4,"MMmM") & " at " & TEXT(Summary!CI34,"0.0%") & " vs " & TEXT(Summary!CH34,"0.0%") & " in " & TEXT(Summary!CH$4,"mmmm YYYY") & " & " & TEXT(Summary!BW34,"0.0%") & " in " & TEXT(Summary!BW$4,"mmmm yyy") -> 3Ws EV penetration in February at 30.7% vs 31.5% in January 2026 & 25.9% in February 2025
A13: =Summary!A36 & " in " & TEXT(Summary!BW$4,"MMmM") & " at " & TEXT(Summary!CI36,"0.0%") & " vs " & TEXT(Summary!CH36,"0.0%") & " in " & TEXT(Summary!CH$4,"mmmm YYYY") & " & " & TEXT(Summary!BW36,"0.0%") & " in " & TEXT(Summary!BW$4,"mmmm yyy") -> CNG PV Penetration in February at 23.6% vs 22.9% in January 2026 & 20.3% in February 2025
A14: =Summary!A37 & " in " & TEXT(Summary!BW$4,"MMmM") & " at " & TEXT(Summary!CI37,"0.0%") & " vs " & TEXT(Summary!CH37,"0.0%") & " in " & TEXT(Summary!CH$4,"mmmm YYYY") & " & " & TEXT(Summary!BW37,"0.0%") & " in " & TEXT(Summary!BW$4,"mmmm yyy") -> Strong Hybrids PV Penetration in February at 2.2% vs 2.2% in January 2026 & 2.4% in February 2025

Sheet PV
B1: 2025\06 - June | CW1: =(DAY(EOMONTH(TODAY(),0))+1)/(DAY(TODAY())-1) -> 32 | CX1: Gross-up factor
B2: 06.03.2025 | BK2: 16 | BL2: =BK2+1 -> 17 | BM2: =BL2+1 -> 18 | BN2: =BM2+1 -> 19 | BO2: =BN2+1 -> 20 | BP2: =BO2+1 -> 21 | BQ2: =BP2+1 -> 22 | BR2: =BQ2+1 -> 23 | BS2: =BR2+1 -> 24 | ... BV2: =BU2+1 -> 27 | BW2: =MONTH(BW3)+1 -> 2 | BX2: =MONTH(BX3)+1 -> 3 | BY2: =MONTH(BY3)+1 -> 4 | BZ2: =MONTH(BZ3)+1 -> 5 | CA2: =MONTH(CA3)+1 -> 6 | CB2: =MONTH(CB3)+1 -> 7 | CC2: =MONTH(CC3)+1 -> 8 | CD2: =MONTH(CD3)+1 -> 9 | ... CH2: =MONTH(CH3)+1 -> 13 | CI2: =IF(MONTH(TODAY())=MONTH(CI3),"",MONTH(CI3)+1) -> 2 | CJ2: =IF(MONTH(TODAY())=MONTH(CJ3)-1,MONTH(CJ3)+2,IF(MONTH(TODAY())=MONTH(CJ3),"",MONTH(CJ3)+1)) -> 3 | CK2: =IF(MONTH(TODAY())=MONTH(CK3)-1,MONTH(CK3)+2,IF(MONTH(TODAY())=MONTH(CK3),"",MONTH(CK3)+1)) | CL2: =IF(MONTH(TODAY())=MONTH(CL3)-1,MONTH(CL3)+2,IF(MONTH(TODAY())=MONTH(CL3),"",MONTH(CL3)+1)) -> 6 | CM2: =IF(MONTH(TODAY())=MONTH(CM3)-1,MONTH(CM3)+2,IF(MONTH(TODAY())=MONTH(CM3),"",MONTH(CM3)+1)) -> 6 | CN2: =IF(MONTH(TODAY())=MONTH(CN3)-1,MONTH(CN3)+2,IF(MONTH(TODAY())=MONTH(CN3),"",MONTH(CN3)+1)) -> 7 | CO2: =IF(MONTH(TODAY())=MONTH(CO3)-1,MONTH(CO3)+2,IF(MONTH(TODAY())=MONTH(CO3),"",MONTH(CO3)+1)) -> 8 | CP2: =IF(MONTH(TODAY())=MONTH(CP3)-1,MONTH(CP3)+2,IF(MONTH(TODAY())=MONTH(CP3),"",MONTH(CP3)+1)) -> 9 | CQ2: =IF(MONTH(TODAY())=MONTH(CQ3)-1,MONTH(CQ3)+2,IF(MONTH(TODAY())=MONTH(CQ3),"",MONTH(CQ3)+1)) -> 10 | ... CT2: =IF(MONTH(TODAY())=MONTH(CT3)-1,MONTH(CT3)+2,IF(MONTH(TODAY())=MONTH(CT3),"",MONTH(CT3)+1)) -> 13 | CW2: =MONTH(TODAY())+1 -> 4
C3: 43466 | D3: =EOMONTH(C3,0)+1 -> 43497 | E3: 43555 | F3: 43585 | G3: 43616 | H3: 43646 | I3: 43677 | J3: 43708 | K3: 43738 | L3: 43769 | M3: 43799 | N3: 43830 | O3: 43861 | P3: 43890 | Q3: 43921 | R3: 43951 | S3: 43982 | T3: 44012 | U3: 44043 | V3: 44074 | W3: 44104 | X3: 44135 | Y3: 44165 | Z3: 44196 | AA3: 44227 | AB3: 44255 | AC3: 44286 | AD3: 44316 | AE3: 44347 | AF3: 44377 | AG3: 44408 | AH3: 44439 | AI3: 44469 | AJ3: 44500 | AK3: 44530 | AL3: 44561 | AM3: 44592 | AN3: 44620 | AO3: 44651 | AP3: 44681 | AQ3: 44712 | AR3: 44742 | AS3: 44773 | AT3: 44804 | AU3: 44834 | AV3: 44865 | AW3: 44895 | AX3: 44926 | AY3: 44957 | AZ3: =EOMONTH(AY3,1) -> 44985 | BA3: =EOMONTH(AZ3,1) -> 45016 | BB3: =EOMONTH(BA3,1) -> 45046 | BC3: =EOMONTH(BB3,1) -> 45077 | BD3: =EOMONTH(BC3,1) -> 45107 | BE3: =EOMONTH(BD3,1) -> 45138 | BF3: =EOMONTH(BE3,1) -> 45169 | BG3: =EOMONTH(BF3,1) -> 45199 | ... BV3: =EOMONTH(BU3,1) -> 45657 | BW3: 45688 | BX3: =EOMONTH(BW3,1) -> 45716 | BY3: =EOMONTH(BX3,1) -> 45747 | BZ3: =EOMONTH(BY3,1) -> 45777 | CA3: =EOMONTH(BZ3,1) -> 45808 | CB3: =EOMONTH(CA3,1) -> 45838 | CC3: =EOMONTH(CB3,1) -> 45869 | CD3: =EOMONTH(CC3,1) -> 45900 | CE3: =EOMONTH(CD3,1) -> 45930 | ... CT3: =EOMONTH(CS3,1) -> 46387 | CW3: MTD | CY3: YTD
B4: TATA MOTORS LTD | C4: 20866 | D4: 15230 | E4: 16095 | F4: 17014 | G4: 16267 | H4: 13261 | I4: 13108 | J4: 10960 | K4: 9475 | L4: 13367 | M4: 14221 | N4: 11347 | O4: 17203 | P4: 13259 | Q4: 16753 | R4: 2415 | S4: 1968 | T4: 9217 | U4: 13950 | V4: 15388 | W4: 17004 | X4: 19778 | Y4: 23846 | Z4: 21592 | AA4: 25198 | AB4: 22632 | AC4: 26743 | AD4: 20221 | AE4: 9957 | AF4: 22353 | AG4: 27149 | AH4: 27711 | AI4: 25304 | AJ4: 27502 | AK4: 31351 | AL4: 33291 | AM4: 26497 | AN4: 6333 | AO4: 2089 | AP4: 991 | AQ4: 731 | AR4: 542 | AS4: 453 | AT4: 332 | AU4: 255 | AV4: 184 | AW4: 203 | AX4: 298 | AY4: 316 | AZ4: 225 | BA4: 349 | BB4: 253 | BC4: 164 | BD4: 108 | BE4: 119 | BF4: 136 | BG4: 98 | BH4: 92 | BI4: 102 | BJ4: 98 | BK4: 118 | BL4: 97 | BM4: 89 | BN4: 86 | BO4: 68 | BP4: 118 | BQ4: 113 | BR4: 94 | BS4: 67 | BT4: 63 | BU4: 60 | BV4: 40 | BW4: 78 | BX4: 34 | BY4: 61 | BZ4: 44 | CA4: 80 | CB4: 122 | CC4: 100 | CD4: 77 | CE4: 42 | CF4: 67 | CG4: 57 | CH4: 51 | CI4: 70 | CJ4: 49.173913 | CK4: 0 | CL4: 0 | CM4: 0 | CN4: 0 | CO4: 0 | CP4: 0 | CQ4: 0 | CR4: 0 | CS4: 0 | CT4: 0 | CW4: 39 | CY4: =SUMIFS($C4:$CV4,$C$3:$CV$3,">="&DATE(2026,1,1),$C$3:$CV$3,"<="&DATE(2026,12,31),$C$2:$CV$2,">"&0)+$CW4 -> 158.17391
B5: TATA MOTORS PASSENGER VEHICLES LTD | C5: 0 | D5: 0 | E5: 0 | F5: 0 | G5: 0 | H5: 0 | I5: 0 | J5: 0 | K5: 0 | L5: 0 | M5: 0 | N5: 0 | O5: 0 | P5: 0 | Q5: 0 | R5: 0 | S5: 0 | T5: 0 | U5: 0 | V5: 0 | W5: 0 | X5: 0 | Y5: 0 | Z5: 0 | AA5: 0 | AB5: 0 | AC5: 0 | AD5: 0 | AE5: 0 | AF5: 0 | AG5: 0 | AH5: 0 | AI5: 0 | AJ5: 0 | AK5: 3 | AL5: 0 | AM5: 7981 | AN5: 27570 | AO5: 34597 | AP5: 35552 | AQ5: 34747 | AR5: 36466 | AS5: 35935 | AT5: 38582 | AU5: 37601 | AV5: 49855 | AW5: 40636 | AX5: 36534 | AY5: 44787 | AZ5: 38886 | BA5: 46485 | BB5: 40779 | BC5: 37575 | BD5: 34679 | BE5: 33460 | BF5: 34296 | BG5: 34637 | BH5: 43588 | BI5: 49062 | BJ5: 38881 | BK5: 47641 | BL5: 39776 | BM5: 38344 | BN5: 40455 | BO5: 35738 | BP5: 32370 | BQ5: 37918 | BR5: 34291 | BS5: 27933 | BT5: 59066 | BU5: 37589 | BV5: 33115 | BW5: 48734 | BX5: 34715 | BY5: 43676 | BZ5: 38970 | CA5: 31569 | CB5: 29598 | CC5: 33281 | CD5: 30573 | CE5: 35040 | CF5: 68573 | CG5: 46396 | CH5: 45281 | CI5: 55200 | CJ5: 45948.609 | CK5: 0 | CL5: 0 | CM5: 0 | CN5: 0 | CO5: 0 | CP5: 0 | CQ5: 0 | CR5: 0 | CS5: 0 | CT5: 0 | CW5: 36442 | CY5: =SUMIFS($C5:$CV5,$C$3:$CV$3,">="&DATE(2026,1,1),$C$3:$CV$3,"<="&DATE(2026,12,31),$C$2:$CV$2,">"&0)+$CW5 -> 137590.61
B6: TATA PASSENGER ELECTRIC MOBILITY LTD | C6: 0 | D6: 0 | E6: 0 | F6: 0 | G6: 0 | H6: 0 | I6: 0 | J6: 0 | K6: 0 | L6: 0 | M6: 0 | N6: 0 | O6: 0 | P6: 0 | Q6: 0 | R6: 0 | S6: 0 | T6: 0 | U6: 0 | V6: 0 | W6: 0 | X6: 0 | Y6: 0 | Z6: 0 | AA6: 0 | AB6: 0 | AC6: 0 | AD6: 0 | AE6: 0 | AF6: 0 | AG6: 0 | AH6: 0 | AI6: 0 | AJ6: 0 | AK6: 0 | AL6: 0 | AM6: 0 | AN6: 0 | AO6: 0 | AP6: 0 | AQ6: 0 | AR6: 0 | AS6: 0 | AT6: 0 | AU6: 0 | AV6: 0 | AW6: 0 | AX6: 0 | AY6: 0 | AZ6: 0 | BA6: 0 | BB6: 482 | BC6: 4242 | BD6: 4849 | BE6: 5053 | BF6: 4476 | BG6: 4110 | BH6: 5369 | BI6: 4980 | BJ6: 4907 | BK6: 5599 | BL6: 5026 | BM6: 7011 | BN6: 5121 | BO6: 5248 | BP6: 4554 | BQ6: 5037 | BR6: 4308 | BS6: 3796 | BT6: 6540 | BU6: 4358 | BV6: 4039 | BW6: 5262 | BX6: 3925 | BY6: 4900 | BZ6: 4762 | CA6: 4606 | CB6: 4956 | CC6: 6296 | CD6: 7513 | CE6: 6715 | CF6: 7693 | CG6: 6463 | CH6: 6731 | CI6: 8205 | CJ6: 5276.7391 | CK6: 0 | CL6: 0 | CM6: 0 | CN6: 0 | CO6: 0 | CP6: 0 | CQ6: 0 | CR6: 0 | CS6: 0 | CT6: 0 | CW6: 4185 | CY6: =SUMIFS($C6:$CV6,$C$3:$CV$3,">="&DATE(2026,1,1),$C$3:$CV$3,"<="&DATE(2026,12,31),$C$2:$CV$2,">"&0)+$CW6 -> 17666.739
